Workbook

Sheet Cover
B2: LBO simplifié - cas d'école sur Fnac Darty (EPA : FNAC)
B3: Exercice de formation - Yvann Ahoure
B4: Toutes les valeurs sont en millions d'euros (M€), sauf mention contraire.
B6: Avertissement important
B7: Exercice de formation à la mécanique d'un LBO (structure de financement, cash sweep, IRR/MOIC, pont de création de valeur), pas une opération réelle ni une recommandation. Cours, actions, EBIT, dette brute et trésorerie FY2025 sont les chiffres publiés de Fnac Darty ; la prime d'offre, le levier, le coût de la dette et le multiple de sortie sont des hypothèses personnelles, identifiées dans l'onglet Assumptions.
B10: Point clé : Fnac Darty est en position de cash net
B11: La dette financière brute hors IFRS16 (958 M€) est inférieure à la trésorerie réelle (1 104 M€) : la cible a 146 M€ de plus de cash que de dette brute. Cette trésorerie étant à son point haut saisonnier au 31 décembre, 8 % du CA sont conservés au bilan ; seul le solde finance une partie du prix (voir projets 2 et 4 du portfolio), ce qui réduit le besoin de dette senior externe et explique le levier modéré retenu (1,7x EBITDA d'entrée, contre un multiple usuel de 3,0x).
B15: Sommaire
B16: Assumptions | C16: Prix d'entrée, position de trésorerie nette, sources et emplois, hypothèses d'exploitation
B17: Debt Schedule | C17: Cash sweep sur 5 ans : EBITDA, impôt, capex, BFR, cascade amortissement obligatoire puis optionnel, ratio de couverture des intérêts
B18: Returns | C18: IRR, MOIC, pont de création de valeur (EBITDA / désendettement / frais) et sensibilité à deux dimensions (prime d'offre x multiple de sortie)
B19: Checks | C19: Contrôles de cohérence du modèle et covenants de crédit hypothétiques (levier, couverture des intérêts)
B21: Sources (données réelles de départ uniquement)
B22: - Cours, actions en circulation : stockanalysis.com / marketscreener.com (12/10/2026).
B23: - EBIT, dette financière brute, trésorerie FY2025 : communiqué de résultats annuels Fnac Darty (25/02/2026).

Sheet Assumptions
B2: Hypothèses
B3: Toutes les valeurs sont en millions d'euros (M€), sauf mention contraire.
B5: PRIX D'ENTRÉE (données réelles + prime hypothétique)
B6: Cours de l'action (réel, 12/10/2026) | C6: 34.4 | E6: Réel - stockanalysis.com / marketscreener.com
B7: Actions en circulation (réel, M) | C7: 29.37
B8: Prime d'offre (hypothèse de l'exercice) | C8: 0.2 | E8: Hypothèse personnelle - prime de contrôle usuelle sur le marché français (15-30 %)
B9: Prix d'offre par action | C9: =C6*(1+C8) -> 41.28
B10: Prix d'acquisition des fonds propres (Equity Purchase Price) | C10: =C9*C7 -> 1212.3936
B12: DONNÉES D'EXPLOITATION RÉELLES ET D&A (FY2025)
B13: Chiffre d'affaires FY2025 (réel) | C13: 10330 | E13: Réel - communiqué FY2025 Fnac Darty
B14: Résultat opérationnel courant FY2025 (EBIT réel) | C14: 203 | E14: Réel - communiqué FY2025 Fnac Darty
B15: D&A (% du CA, hypothèse) | C15: 0.034 | E15: Cohérente avec l'hypothèse de D&A du projet 4 (Transaction Services DD) ; la société ne publie pas le D&A hors IFRS16 séparément.
B16: D&A d'entrée FY2025 (estimée) | C16: =C13*C15 -> 351.22
B17: EBITDA d'entrée (= EBIT réel + D&A estimée) | C17: =C14+C16 -> 554.22
B19: DETTE EXISTANTE ET TRÉSORERIE (réelles, FY2025, hors IFRS16)
B20: Dette financière brute FY2025 (réelle, hors IFRS16) | C20: 958 | E20: Réelle - communiqué de résultats annuels Fnac Darty (25/02/2026).
B21: Trésorerie et équivalents de trésorerie FY2025 (réelle) | C21: 1104 | E21: Réelle - communiqué FY2025 ; cohérente avec le projet 2 (modèle 3 états + DCF).
B22: Dette nette FY2025 (position de trésorerie nette, réelle) | C22: =C20-C21 -> -146 | E22: 958 - 1 104 = -146 M€ : Fnac Darty est en position de cash net, pas de dette nette. Lecture cohérente avec celle retenue dans le projet 2.
B24: EMPLOIS (USES)
B25: Refinancement de la dette brute existante | C25: =C20 -> 958
B26: Emplois avant frais (fonds propres + refinancement de la dette brute) | C26: =C10+C25 -> 2170.3936
B27: Frais de transaction (% des emplois avant frais) | C27: 0.02 | E27: Hypothèse standard (frais de conseil, financement, juridique)
B28: Frais de transaction | C28: =C26*C27 -> 43.407872
B29: Total des emplois (Uses) | C29: =C26+C28 -> 2213.8015
B31: SOURCES (FINANCEMENT)
B32: Trésorerie conservée au bilan (exploitation et saisonnalité, % du CA) | C32: 0.08 | E32: Hypothèse personnelle : trésorerie au 31/12 gonflée par la saisonnalité (BFR négatif), en partie non mobilisable.
B33: Trésorerie conservée au bilan (M€) | C33: =C13*C32 -> 826.4
B34: Trésorerie excédentaire utilisée pour financer la transaction | C34: =C21-C33 -> 277.6 | E34: Seule la trésorerie au-delà du besoin d'exploitation et saisonnier réduit le besoin de financement externe.
B35: Besoin de financement externe (dette + fonds propres) | C35: =C29-C34 -> 1936.2015
B36: Valeur d'entreprise à l'entrée (VE = prix des fonds propres + dette nette) | C36: =C10+C22 -> 1066.3936
B37: Multiple d'entrée (VE / EBITDA d'entrée, calculé) | C37: =C36/C17 -> 1.9241341
B38: Levier senior (x EBITDA d'entrée, hypothèse) | C38: 1.7 | E38: Revu à la baisse par rapport à un levier usuel de 3,0x : la cible part d'une position de cash net et une partie de sa trésorerie finance le prix, ce qui réduit le besoin de dette externe.
B39: Dette senior à l'entrée | C39: =C38*C17 -> 942.174
B40: Taux d'intérêt de la dette senior | C40: 0.065 | E40: Hypothèse personnelle, cohérente avec le marché du leveraged loan en 2026
B41: Apport en fonds propres du sponsor (plug) | C41: =C35-C39 -> 994.02747
B42: Apport en fonds propres (% du besoin de financement externe) | C42: =C41/C35 -> 0.51339052
B43: Total des sources (contrôle = total des emplois) | C43: =C34+C39+C41 -> 2213.8015
B45: HYPOTHÈSES D'EXPLOITATION (5 ans, personnelles)
B46: Croissance de l'EBITDA (%/an) | C46: 0.03
B47: Croissance du chiffre d'affaires (%/an) | C47: 0.02
...

Sheet Debt Schedule
B2: Cash sweep - 5 ans
B3: Toutes les valeurs sont en millions d'euros (M€), sauf mention contraire.
C5: Année 1 | D5: Année 2 | E5: Année 3 | F5: Année 4 | G5: Année 5
B6: Chiffre d'affaires | C6: =Assumptions!$C$13*(1+Assumptions!$C$47) -> 10536.6 | D6: =C6*(1+Assumptions!$C$47) -> 10747.332 | E6: =D6*(1+Assumptions!$C$47) -> 10962.279 | F6: =E6*(1+Assumptions!$C$47) -> 11181.524 | G6: =F6*(1+Assumptions!$C$47) -> 11405.155
B7: EBITDA | C7: =Assumptions!$C$17*(1+Assumptions!$C$46) -> 570.8466 | D7: =C7*(1+Assumptions!$C$46) -> 587.972 | E7: =D7*(1+Assumptions!$C$46) -> 605.61116 | F7: =E7*(1+Assumptions!$C$46) -> 623.77949 | G7: =F7*(1+Assumptions!$C$46) -> 642.49288
B8: D&A (% du CA, réf. Assumptions) | C8: =C6*Assumptions!$C$15 -> 358.2444 | D8: =D6*Assumptions!$C$15 -> 365.40929 | E8: =E6*Assumptions!$C$15 -> 372.71747 | F8: =F6*Assumptions!$C$15 -> 380.17182 | G8: =G6*Assumptions!$C$15 -> 387.77526
B9: EBIT (= EBITDA - D&A) | C9: =C7-C8 -> 212.6022 | D9: =D7-D8 -> 222.56271 | E9: =E7-E8 -> 232.89368 | F9: =F7-F8 -> 243.60767 | G9: =G7-G8 -> 254.71762
B10: Dette senior en début de période | C10: =Assumptions!$C$39 -> 942.174 | D10: =C18 -> 680.84662 | E10: =D18 -> 414.56412 | F10: =E18 -> 143.09455 | G10: =F18 -> 0
B11: Charge d'intérêt | C11: =C10*Assumptions!$C$40 -> 61.24131 | D11: =D10*Assumptions!$C$40 -> 44.25503 | E11: =E10*Assumptions!$C$40 -> 26.946668 | F11: =F10*Assumptions!$C$40 -> 9.3011459 | G11: =G10*Assumptions!$C$40 -> 0
B12: Résultat avant impôt (EBT = EBIT - intérêts) | C12: =C9-C11 -> 151.36089 | D12: =D9-D11 -> 178.30768 | E12: =E9-E11 -> 205.94702 | F12: =F9-F11 -> 234.30652 | G12: =G9-G11 -> 254.71762
B13: Impôt (= MAX(EBT,0) x taux d'IS) | C13: =MAX(C12,0)*Assumptions!$C$50 -> 37.840223 | D13: =MAX(D12,0)*Assumptions!$C$50 -> 44.57692 | E13: =MAX(E12,0)*Assumptions!$C$50 -> 51.486754 | F13: =MAX(F12,0)*Assumptions!$C$50 -> 58.576631 | G13: =MAX(G12,0)*Assumptions!$C$50 -> 63.679404
B14: Capex | C14: =C6*Assumptions!$C$48 -> 263.415 | D14: =D6*Assumptions!$C$48 -> 268.6833 | E14: =E6*Assumptions!$C$48 -> 274.05697 | F14: =F6*Assumptions!$C$48 -> 279.53811 | G14: =G6*Assumptions!$C$48 -> 285.12887
B15: Variation du BFR (impact trésorerie) | C15: =-(C6-Assumptions!$C$13)*Assumptions!$C$49 -> -8.264 | D15: =-(D6-C6)*Assumptions!$C$49 -> -8.42928 | E15: =-(E6-D6)*Assumptions!$C$49 -> -8.5978656 | F15: =-(F6-E6)*Assumptions!$C$49 -> -8.7698229 | G15: =-(G6-F6)*Assumptions!$C$49 -> -8.9452194
B16: FCF disponible (désendettement + accumulation de trésorerie) | C16: =C7-C13-C14+C15 -> 261.32738 | D16: =D7-D13-D14+D15 -> 266.2825 | E16: =E7-E13-E14+E15 -> 271.46957 | F16: =F7-F13-F14+F15 -> 276.89493 | G16: =G7-G13-G14+G15 -> 284.73939
B17: Remboursement de la dette senior (cash sweep) | C17: =MIN(MAX(C16,0),C10) -> 261.32738 | D17: =MIN(MAX(D16,0),D10) -> 266.2825 | E17: =MIN(MAX(E16,0),E10) -> 271.46957 | F17: =MIN(MAX(F16,0),F10) -> 143.09455 | G17: =MIN(MAX(G16,0),G10) -> 0
B18: Dette senior en fin de période | C18: =C10-C17 -> 680.84662 | D18: =D10-D17 -> 414.56412 | E18: =E10-E17 -> 143.09455 | F18: =F10-F17 -> 0 | G18: =G10-G17 -> 0
B20: Trésorerie excédentaire accumulée sur la période | C20: =C16-C17 -> 0 | D20: =D16-D17 -> 0 | E20: =E16-E17 -> 0 | F20: =F16-F17 -> 133.80038 | G20: =G16-G17 -> 284.73939
B21: Trésorerie excédentaire accumulée, cumulée fin de période | C21: =C20 -> 0 | D21: =C21+D20 -> 0 | E21: =D21+E20 -> 0 | F21: =E21+F20 -> 133.80038 | G21: =F21+G20 -> 418.53977
B23: Lecture : le FCF disponible (ligne 16) rembourse la dette senior en priorité (cash sweep à 100 %) ; une fois la dette intégralement remboursée (ligne 18 = 0), le FCF excédentaire s'accumule en trésorerie (lignes 20-21) plutôt que de disparaître du modèle.
B25: MÉMO : CASCADE DE REMBOURSEMENT ET RATIO DE COUVERTURE
B26: dont amortissement obligatoire (mémo, priorité de paiement) | C26: =MIN(Assumptions!$C$54*Assumptions!$C$39,C17) -> 9.42174 | D26: =MIN(Assumptions!$C$54*Assumptions!$C$39,D17) -> 9.42174 | E26: =MIN(Assumptions!$C$54*Assumptions!$C$39,E17) -> 9.42174 | F26: =MIN(Assumptions!$C$54*Assumptions!$C$39,F17) -> 9.42174 | G26: =MIN(Assumptions!$C$54*Assumptions!$C$39,G17) -> 0
B27: dont remboursement optionnel, cash sweep (mémo, résiduel) | C27: =C17-C26 -> 251.90564 | D27: =D17-D26 -> 256.86076 | E27: =E17-E26 -> 262.04783 | F27: =F17-F26 -> 133.67281 | G27: =G17-G26 -> 0
B28: Lecture : le remboursement total (ligne 17) suit la cascade standard d'un prêt à terme en LBO, l'amortissement obligatoire est réglé en priorité, puis l'excédent de trésorerie disponible (cash sweep) est affecté en remboursement optionnel du solde restant, conformément à la hiérarchie décrite dans le guide BIWS LBO Model (Key Rule n°3 : les remboursements obligatoires sont toujours réglés avant les remboursements optionnels).
B29: Ratio de couverture des intérêts (EBITDA / charge d'intérêts) | C29: =IFERROR(C7/C11,0) -> 9.321267 | D29: =IFERROR(D7/D11,0) -> 13.285992 | E29: =IFERROR(E7/E11,0) -> 22.474436 | F29: =IFERROR(F7/F11,0) -> 67.0648 | G29: =IFERROR(G7/G11,0) -> 0
B30: Lecture : en Année 5, la dette senior est intégralement remboursée (charge d'intérêts nulle), le ratio affiche 0 par convention de calcul (IFERROR) plutôt qu'une erreur de division ; le contrôle de couverture des intérêts (onglet Checks) ne porte donc que sur les années où la dette senior porte encore intérêt.

Sheet Returns
B2: Rendement du sponsor : IRR, MOIC, pont de création de valeur
B3: Toutes les valeurs sont en millions d'euros (M€), sauf mention contraire.
B5: SORTIE À 5 ANS
B6: EBITDA de sortie (Année 5) | C6: ='Debt Schedule'!G7 -> 642.49288
B7: Multiple de sortie | C7: =Assumptions!C51 -> 1.9241341
B8: Valeur d'entreprise de sortie | C8: =C6*C7 -> 1236.2425
B9: - Dette senior restante (fin Année 5) | C9: ='Debt Schedule'!G18 -> 0
B10: + Trésorerie conservée au bilan (réf. Assumptions) | C10: =Assumptions!C33 -> 826.4
B11: + Trésorerie excédentaire accumulée (fin Année 5) | C11: ='Debt Schedule'!G21 -> 418.53977
B12: -> Valeur des fonds propres à la sortie | C12: =C8-C9+C10+C11 -> 2481.1822
B14: RENDEMENT DU SPONSOR
B15: Apport en fonds propres à l'entrée | C15: =Assumptions!C41 -> 994.02747
B16: Valeur des fonds propres à la sortie | C16: =C12 -> 2481.1822
B17: MOIC (multiple sur capital investi) | C17: =C16/C15 -> 2.4960902
B18: Durée de détention (années) | C18: 5
B19: IRR (= MOIC^(1/n) - 1) | C19: =C17^(1/C18)-1 -> 0.20074851
B21: PONT DE CRÉATION DE VALEUR (fonds propres)
B22: Entrée : trésorerie conservée au bilan (réf. Assumptions) | C22: =Assumptions!C33 -> 826.4
B23: Dette nette de la structure à l'entrée (dette senior - trésorerie conservée) | C23: =Assumptions!C39-C22 -> 115.774
B24: Dette nette de la structure à la sortie | C24: =C9-(C10+C11) -> -1244.9398
B25: Contribution croissance de l'EBITDA (à multiple d'entrée constant) | C25: =(C6-Assumptions!C17)*Assumptions!C37 -> 169.84885
B26: Contribution variation de multiple | C26: =C6*(C7-Assumptions!C37) -> 0
B27: Contribution désendettement (dette nette entrée - dette nette sortie) | C27: =C23-C24 -> 1360.7138
B28: - Frais de transaction (valeur détruite à la clôture) | C28: =-Assumptions!C28 -> -43.407872
B29: Total création de valeur (contrôle) | C29: =SUM(C25:C28) -> 1487.1547
B30: Création de valeur réelle (sortie - entrée, contrôle croisé) | C30: =C16-C15 -> 1487.1547
B32: Lecture : l'apport en fonds propres du sponsor représente 44,9 % du total des emplois (51,3 % du besoin de financement externe, réf. Assumptions C42), un niveau cohérent avec les structures LBO actuelles. Le rendement repose sur le désendettement et l'accumulation de trésorerie, sans aucune expansion de multiple.
B34: SENSIBILITÉ DE L'IRR : PRIME D'OFFRE x MULTIPLE DE SORTIE
B35: Lecture : dans ce modèle, la dette senior (fixée en % de l'EBITDA d'entrée) et le calendrier de désendettement ne dépendent ni de la prime payée ni du multiple de sortie ; seuls l'apport en fonds propres à l'entrée et la valeur des fonds propres à la sortie varient avec ces deux paramètres, ce qui permet un calcul direct par formule pour chaque scénario (construction analogue aux tables de sensibilité du guide BIWS LBO Model, page 19 : prime d'offre x multiple de sortie).
B37: Prime d'offre \ multiple de sortie (VE/EBITDA) | C37: =$C$7-0.4 -> 1.5241341 | D37: =$C$7-0.2 -> 1.7241341 | E37: =$C$7 -> 1.9241341 | F37: =$C$7+0.2 -> 2.1241341 | G37: =$C$7+0.4 -> 2.3241341
B38: =Assumptions!$C$8-0.2 -> 0 | C38: =(('Debt Schedule'!$G$7*C$37-'Debt Schedule'!$G$18+Assumptions!$C$33+'Debt Schedule'!$G$21)/((Assumptions!$C$6*(1+$B38)*Assumptions!$C$7+Assumptions!$C$20)*(1+Assumptions!$C$27)-Assumptions!$C$34-Assumptions!$C$39))^(1/$C$18)-1 -> 0.2306589 | D38: =(('Debt Schedule'!$G$7*D$37-'Debt Schedule'!$G$18+Assumptions!$C$33+'Debt Schedule'!$G$21)/((Assumptions!$C$6*(1+$B38)*Assumptions!$C$7+Assumptions!$C$20)*(1+Assumptions!$C$27)-Assumptions!$C$34-Assumptions!$C$39))^(1/$C$18)-1 -> 0.24456109 | E38: =(('Debt Schedule'!$G$7*E$37-'Debt Schedule'!$G$18+Assumptions!$C$33+'Debt Schedule'!$G$21)/((Assumptions!$C$6*(1+$B38)*Assumptions!$C$7+Assumptions!$C$20)*(1+Assumptions!$C$27)-Assumptions!$C$34-Assumptions!$C$39))^(1/$C$18)-1 -> 0.25786851 | F38: =(('Debt Schedule'!$G$7*F$37-'Debt Schedule'!$G$18+Assumptions!$C$33+'Debt Schedule'!$G$21)/((Assumptions!$C$6*(1+$B38)*Assumptions!$C$7+Assumptions!$C$20)*(1+Assumptions!$C$27)-Assumptions!$C$34-Assumptions!$C$39))^(1/$C$18)-1 -> 0.27063552 | G38: =(('Debt Schedule'!$G$7*G$37-'Debt Schedule'!$G$18+Assumptions!$C$33+'Debt Schedule'!$G$21)/((Assumptions!$C$6*(1+$B38)*Assumptions!$C$7+Assumptions!$C$20)*(1+Assumptions!$C$27)-Assumptions!$C$34-Assumptions!$C$39))^(1/$C$18)-1 -> 0.28290912
B39: =Assumptions!$C$8-0.1 -> 0.1 | C39: =(('Debt Schedule'!$G$7*C$37-'Debt Schedule'!$G$18+Assumptions!$C$33+'Debt Schedule'!$G$21)/((Assumptions!$C$6*(1+$B39)*Assumptions!$C$7+Assumptions!$C$20)*(1+Assumptions!$C$27)-Assumptions!$C$34-Assumptions!$C$39))^(1/$C$18)-1 -> 0.20077373 | D39: =(('Debt Schedule'!$G$7*D$37-'Debt Schedule'!$G$18+Assumptions!$C$33+'Debt Schedule'!$G$21)/((Assumptions!$C$6*(1+$B39)*Assumptions!$C$7+Assumptions!$C$20)*(1+Assumptions!$C$27)-Assumptions!$C$34-Assumptions!$C$39))^(1/$C$18)-1 -> 0.21433832 | E39: =(('Debt Schedule'!$G$7*E$37-'Debt Schedule'!$G$18+Assumptions!$C$33+'Debt Schedule'!$G$21)/((Assumptions!$C$6*(1+$B39)*Assumptions!$C$7+Assumptions!$C$20)*(1+Assumptions!$C$27)-Assumptions!$C$34-Assumptions!$C$39))^(1/$C$18)-1 -> 0.22732258 | F39: =(('Debt Schedule'!$G$7*F$37-'Debt Schedule'!$G$18+Assumptions!$C$33+'Debt Schedule'!$G$21)/((Assumptions!$C$6*(1+$B39)*Assumptions!$C$7+Assumptions!$C$20)*(1+Assumptions!$C$27)-Assumptions!$C$34-Assumptions!$C$39))^(1/$C$18)-1 -> 0.23977956 | G39: =(('Debt Schedule'!$G$7*G$37-'Debt Schedule'!$G$18+Assumptions!$C$33+'Debt Schedule'!$G$21)/((Assumptions!$C$6*(1+$B39)*Assumptions!$C$7+Assumptions!$C$20)*(1+Assumptions!$C$27)-Assumptions!$C$34-Assumptions!$C$39))^(1/$C$18)-1 -> 0.2517551
B40: =Assumptions!$C$8 -> 0.2 | C40: =(('Debt Schedule'!$G$7*C$37-'Debt Schedule'!$G$18+Assumptions!$C$33+'Debt Schedule'!$G$21)/((Assumptions!$C$6*(1+$B40)*Assumptions!$C$7+Assumptions!$C$20)*(1+Assumptions!$C$27)-Assumptions!$C$34-Assumptions!$C$39))^(1/$C$18)-1 -> 0.17477449 | D40: =(('Debt Schedule'!$G$7*D$37-'Debt Schedule'!$G$18+Assumptions!$C$33+'Debt Schedule'!$G$21)/((Assumptions!$C$6*(1+$B40)*Assumptions!$C$7+Assumptions!$C$20)*(1+Assumptions!$C$27)-Assumptions!$C$34-Assumptions!$C$39))^(1/$C$18)-1 -> 0.18804538 | E40: =(('Debt Schedule'!$G$7*E$37-'Debt Schedule'!$G$18+Assumptions!$C$33+'Debt Schedule'!$G$21)/((Assumptions!$C$6*(1+$B40)*Assumptions!$C$7+Assumptions!$C$20)*(1+Assumptions!$C$27)-Assumptions!$C$34-Assumptions!$C$39))^(1/$C$18)-1 -> 0.20074851 | F40: =(('Debt Schedule'!$G$7*F$37-'Debt Schedule'!$G$18+Assumptions!$C$33+'Debt Schedule'!$G$21)/((Assumptions!$C$6*(1+$B40)*Assumptions!$C$7+Assumptions!$C$20)*(1+Assumptions!$C$27)-Assumptions!$C$34-Assumptions!$C$39))^(1/$C$18)-1 -> 0.21293576 | G40: =(('Debt Schedule'!$G$7*G$37-'Debt Schedule'!$G$18+Assumptions!$C$33+'Debt Schedule'!$G$21)/((Assumptions!$C$6*(1+$B40)*Assumptions!$C$7+Assumptions!$C$20)*(1+Assumptions!$C$27)-Assumptions!$C$34-Assumptions!$C$39))^(1/$C$18)-1 -> 0.22465202
B41: =Assumptions!$C$8+0.1 -> 0.3 | C41: =(('Debt Schedule'!$G$7*C$37-'Debt Schedule'!$G$18+Assumptions!$C$33+'Debt Schedule'!$G$21)/((Assumptions!$C$6*(1+$B41)*Assumptions!$C$7+Assumptions!$C$20)*(1+Assumptions!$C$27)-Assumptions!$C$34-Assumptions!$C$39))^(1/$C$18)-1 -> 0.15182487 | D41: =(('Debt Schedule'!$G$7*D$37-'Debt Schedule'!$G$18+Assumptions!$C$33+'Debt Schedule'!$G$21)/((Assumptions!$C$6*(1+$B41)*Assumptions!$C$7+Assumptions!$C$20)*(1+Assumptions!$C$27)-Assumptions!$C$34-Assumptions!$C$39))^(1/$C$18)-1 -> 0.16483651 | E41: =(('Debt Schedule'!$G$7*E$37-'Debt Schedule'!$G$18+Assumptions!$C$33+'Debt Schedule'!$G$21)/((Assumptions!$C$6*(1+$B41)*Assumptions!$C$7+Assumptions!$C$20)*(1+Assumptions!$C$27)-Assumptions!$C$34-Assumptions!$C$39))^(1/$C$18)-1 -> 0.17729147 | F41: =(('Debt Schedule'!$G$7*F$37-'Debt Schedule'!$G$18+Assumptions!$C$33+'Debt Schedule'!$G$21)/((Assumptions!$C$6*(1+$B41)*Assumptions!$C$7+Assumptions!$C$20)*(1+Assumptions!$C$27)-Assumptions!$C$34-Assumptions!$C$39))^(1/$C$18)-1 -> 0.18924065 | G41: =(('Debt Schedule'!$G$7*G$37-'Debt Schedule'!$G$18+Assumptions!$C$33+'Debt Schedule'!$G$21)/((Assumptions!$C$6*(1+$B41)*Assumptions!$C$7+Assumptions!$C$20)*(1+Assumptions!$C$27)-Assumptions!$C$34-Assumptions!$C$39))^(1/$C$18)-1 -> 0.20072802
B42: =Assumptions!$C$8+0.2 -> 0.4 | C42: =(('Debt Schedule'!$G$7*C$37-'Debt Schedule'!$G$18+Assumptions!$C$33+'Debt Schedule'!$G$21)/((Assumptions!$C$6*(1+$B42)*Assumptions!$C$7+Assumptions!$C$20)*(1+Assumptions!$C$27)-Assumptions!$C$34-Assumptions!$C$39))^(1/$C$18)-1 -> 0.13132715 | D42: =(('Debt Schedule'!$G$7*D$37-'Debt Schedule'!$G$18+Assumptions!$C$33+'Debt Schedule'!$G$21)/((Assumptions!$C$6*(1+$B42)*Assumptions!$C$7+Assumptions!$C$20)*(1+Assumptions!$C$27)-Assumptions!$C$34-Assumptions!$C$39))^(1/$C$18)-1 -> 0.14410723 | E42: =(('Debt Schedule'!$G$7*E$37-'Debt Schedule'!$G$18+Assumptions!$C$33+'Debt Schedule'!$G$21)/((Assumptions!$C$6*(1+$B42)*Assumptions!$C$7+Assumptions!$C$20)*(1+Assumptions!$C$27)-Assumptions!$C$34-Assumptions!$C$39))^(1/$C$18)-1 -> 0.15634055 | F42: =(('Debt Schedule'!$G$7*F$37-'Debt Schedule'!$G$18+Assumptions!$C$33+'Debt Schedule'!$G$21)/((Assumptions!$C$6*(1+$B42)*Assumptions!$C$7+Assumptions!$C$20)*(1+Assumptions!$C$27)-Assumptions!$C$34-Assumptions!$C$39))^(1/$C$18)-1 -> 0.16807708 | G42: =(('Debt Schedule'!$G$7*G$37-'Debt Schedule'!$G$18+Assumptions!$C$33+'Debt Schedule'!$G$21)/((Assumptions!$C$6*(1+$B42)*Assumptions!$C$7+Assumptions!$C$20)*(1+Assumptions!$C$27)-Assumptions!$C$34-Assumptions!$C$39))^(1/$C$18)-1 -> 0.17936003
B44: La cellule encadrée (prime d'offre 20 %, multiple de sortie égal au multiple d'entrée) correspond exactement au scénario central présenté ci-dessus (IRR 20,1 %, ligne 19) : elle sert de contrôle de cohérence entre la table de sensibilité et le calcul central du modèle.

Sheet Checks
B2: Contrôles de cohérence
B5: Contrôle | D5: Résultat
B6: Total des sources = total des emplois (Assumptions) | D6: =IF(ROUND(Assumptions!C43-Assumptions!C29,1)=0,"OK","A VERIFIER") -> OK
B7: Pont de création de valeur = création de valeur réelle (sortie - entrée) | D7: =IF(ROUND(Returns!C29-Returns!C30,1)=0,"OK","A VERIFIER") -> OK
B8: Dette senior ne devient jamais négative sur les 5 ans | D8: =IF(MIN('Debt Schedule'!C18:G18)>=0,"OK","A VERIFIER") -> OK
B9: Apport en fonds propres du sponsor positif | D9: =IF(Assumptions!C41>0,"OK","A VERIFIER") -> OK
B10: FCF disponible positif chaque année (le sweep ne force pas une valeur négative) | D10: =IF(MIN('Debt Schedule'!C16:G16)>=0,"OK","A VERIFIER") -> OK
B11: MOIC et IRR cohérents (MOIC > 1 si IRR > 0) | D11: =IF(AND(Returns!C17>1,Returns!C19>0),"OK","A VERIFIER") -> OK
B12: Levier senior à l'entrée respecte le covenant hypothétique (dette senior / EBITDA) | D12: =IF(Assumptions!$C$38<=Assumptions!$C$55,"OK","A VERIFIER") -> OK
B13: Couverture des intérêts respecte le covenant hypothétique chaque année (EBITDA / intérêts) | D13: =IF(_xlfn.MINIFS('Debt Schedule'!$C$29:$G$29,'Debt Schedule'!$C$11:$G$11,">0")>=Assumptions!$C$56,"OK","A VERIFIER") -> OK
B15: Synthèse | C15: =IF(COUNTIF(D6:D13,"OK")=8,"Tous les contrôles sont OK","Au moins un contrôle à vérifier") -> Tous les contrôles sont OK
