Workbook

Sheet Cover
B2: Business Plan & Pitch Deck - KobaPay (épargne et paiement mobile, UEMOA)
B3: Exercice de formation - Yvann Ahoure
B4: Toutes les valeurs d'exploitation sont en millions de FCFA (M FCFA) ; la levée de fonds est exprimée en euros (EUR).
B6: Nature de l'exercice
B7: KobaPay est une startup fictive, créée pour ce portfolio afin de démontrer la construction d'un business plan complet et d'un pitch deck d'investisseurs. Les données de marché citées (taux d'inclusion financière UEMOA, volumes de transactions mobile money) sont réelles et sourcées - voir Sources ci-dessous. Toutes les données propres à KobaPay (utilisateurs, revenus, coûts, levée de fonds, valorisation) sont des hypothèses inventées pour l'exercice et ne décrivent aucune société réelle.
B12: Concept
B13: Plateforme mobile de paiement et d'épargne de groupe digitalisée (tontine), ciblant les utilisateurs non ou sous-bancarisés de la zone UEMOA (lancement en Côte d'Ivoire, extension au Sénégal à partir de l'année 3). Trois sources de revenu construites progressivement : commission sur les transferts et paiements marchands, frais de gestion sur l'épargne de groupe, puis marge nette d'intérêt sur le micro-crédit à partir de l'année 3, une fois l'historique d'épargne des utilisateurs disponible.
B18: Sommaire
B19: Assumptions | C19: Hypothèses de croissance, de revenu, de coûts et de financement
B20: Revenue Build | C20: Construction du chiffre d'affaires par ligne de produit (transactionnel, épargne, crédit)
B21: P&L | C21: Compte de résultat sur 5 ans (2027F-2031F)
B22: Cash Flow | C22: Trésorerie, financement et trajectoire de runway
B23: Funding & Cap Table | C23: Levée de fonds, valorisation, table de capitalisation, utilisation des fonds
B24: Dashboard | C24: Graphiques de synthèse
B25: Checks | C25: Contrôles de cohérence du modèle
B27: Sources (données de marché réelles)
B28: - BCEAO/UEMOA, Stratégie régionale d'inclusion financière 2025-2030 : taux d'inclusion financière de 72,3 % en 2023 (contre 47 % en 2016), cible de 90 % d'ici 2030.
B29: - GSMA, State of the Industry Report on Mobile Money 2026 : 498 Md$ de valeur de transactions mobile money en Afrique de l'Ouest en 2025.
B30: - Taux de change FCFA/EUR : parité fixe de 655,957 FCFA pour 1 EUR (zone UEMOA, arrimage à l'euro).

Sheet Assumptions
B2: Hypothèses - KobaPay
B3: Cellules bleues = hypothèses modifiables. Toutes les hypothèses propres à KobaPay sont inventées pour l'exercice.
B5: Croissance utilisateurs
B6: Utilisateurs actifs, année 1 (2027F) | C6: 25000
B7: Croissance utilisateurs, année 2 | C7: 2.6
B8: Croissance utilisateurs, année 3 | C8: 1.45
B9: Croissance utilisateurs, année 4 | C9: 0.7
B10: Croissance utilisateurs, année 5 | C10: 0.45
B12: Revenu transactionnel
B13: Volume transactionnel mensuel moyen par utilisateur actif, année 1 (FCFA) | C13: 35000
B14: Croissance annuelle du volume moyen par utilisateur | C14: 0.08
B15: Taux de commission (take rate) sur le volume transactionnel | C15: 0.013
B17: Épargne de groupe (tontine digitale)
B18: % des utilisateurs actifs utilisant le produit d'épargne | C18: 0.35
B19: Solde d'épargne moyen par épargnant, année 1 (FCFA) | C19: 150000
B20: Croissance annuelle du solde moyen | C20: 0.1
B21: Frais de gestion annuel sur encours d'épargne (AUM) | C21: 0.015
B23: Micro-crédit (lancement année 3)
B24: % des épargnants utilisant le micro-crédit, à partir de l'année 3 | C24: 0.12
B25: Encours de crédit moyen par emprunteur (FCFA) | C25: 80000
B26: Marge nette d'intérêt sur encours de crédit | C26: 0.09
B28: Coûts d'acquisition et d'exploitation
B29: Coût d'acquisition client (CAC), année 1 (FCFA / nouvel utilisateur) | C29: 2500
B30: Baisse annuelle du CAC (gains d'efficacité) | C30: 0.08
B31: Coûts techniques et hébergement (% du chiffre d'affaires) | C31: 0.12
B32: Taux d'IS (UEMOA) | C32: 0.25
B34: Postes de coûts par année (M FCFA) | C34: 2027F | D34: 2028F | E34: 2029F | F34: 2030F | G34: 2031F
B35: Masse salariale (M FCFA) | C35: 60 | D35: 140 | E35: 260 | F35: 420 | G35: 600
B36: Frais généraux et administratifs (M FCFA) | C36: 25 | D36: 45 | E36: 70 | F36: 100 | G36: 130
B37: Conformité réglementaire et licence EME (M FCFA) | C37: 40 | D37: 30 | E37: 30 | F37: 35 | G37: 35
B38: Capex (M FCFA) | C38: 20 | D38: 35 | E38: 55 | F38: 70 | G38: 85
B39: Durée d'amortissement des investissements (années) | C39: 3
B40: Variation du BFR (% de la variation du chiffre d'affaires) | C40: 0.03
B41: Taux de rémunération de la trésorerie | C41: 0.03
B43: Financement (levée de fonds)
B44: Apport initial des fondateurs (EUR) | C44: 50000
B45: Montant de la levée - seed round (EUR) | C45: 550000
B46: Valorisation pre-money (EUR) | C46: 2450000
B47: Taux de change FCFA/EUR (parité fixe UEMOA) | C47: 655.957
B48: Pool ESOP créé à la levée (% post-money) | C48: 0.1
...

Sheet Revenue Build
B2: Revenue Build - KobaPay
B3: Toutes les valeurs sont en millions de FCFA (M FCFA), sauf utilisateurs (nombre) et volumes/soldes unitaires (FCFA).
C5: 2027F | D5: 2028F | E5: 2029F | F5: 2030F | G5: 2031F
B6: Utilisateurs actifs (fin d'année) | C6: =Assumptions!$C$6 -> 25000 | D6: =C6*(1+Assumptions!$C$7) -> 90000 | E6: =D6*(1+Assumptions!$C$8) -> 220500 | F6: =E6*(1+Assumptions!$C$9) -> 374850 | G6: =F6*(1+Assumptions!$C$10) -> 543532.5
B7: Nouveaux utilisateurs dans l'année | C7: =C6 -> 25000 | D7: =D6-C6 -> 65000 | E7: =E6-D6 -> 130500 | F7: =F6-E6 -> 154350 | G7: =G6-F6 -> 168682.5
B9: Revenu transactionnel
B10: Volume transactionnel mensuel moyen / utilisateur (FCFA) | C10: =Assumptions!$C$13 -> 35000 | D10: =C10*(1+Assumptions!$C$14) -> 37800 | E10: =D10*(1+Assumptions!$C$14) -> 40824 | F10: =E10*(1+Assumptions!$C$14) -> 44089.92 | G10: =F10*(1+Assumptions!$C$14) -> 47617.114
B11: Volume transactionnel annuel (M FCFA) | C11: =C6*C10*12/1000000 -> 10500 | D11: =D6*D10*12/1000000 -> 40824 | E11: =E6*E10*12/1000000 -> 108020.3 | F11: =F6*F10*12/1000000 -> 198325.28 | G11: =G6*G10*12/1000000 -> 310577.39
B12: Revenu transactionnel (M FCFA) | C12: =C11*Assumptions!$C$15 -> 136.5 | D12: =D11*Assumptions!$C$15 -> 530.712 | E12: =E11*Assumptions!$C$15 -> 1404.264 | F12: =F11*Assumptions!$C$15 -> 2578.2286 | G12: =G11*Assumptions!$C$15 -> 4037.506
B14: Revenu épargne (tontine digitale)
B15: % utilisateurs épargnants | C15: =Assumptions!$C$18 -> 0.35 | D15: =Assumptions!$C$18 -> 0.35 | E15: =Assumptions!$C$18 -> 0.35 | F15: =Assumptions!$C$18 -> 0.35 | G15: =Assumptions!$C$18 -> 0.35
B16: Nombre d'épargnants | C16: =C6*C15 -> 8750 | D16: =D6*D15 -> 31500 | E16: =E6*E15 -> 77175 | F16: =F6*F15 -> 131197.5 | G16: =G6*G15 -> 190236.38
B17: Solde d'épargne moyen par épargnant (FCFA) | C17: =Assumptions!$C$19 -> 150000 | D17: =C17*(1+Assumptions!$C$20) -> 165000 | E17: =D17*(1+Assumptions!$C$20) -> 181500 | F17: =E17*(1+Assumptions!$C$20) -> 199650 | G17: =F17*(1+Assumptions!$C$20) -> 219615
B18: Encours d'épargne géré - AUM (M FCFA) | C18: =C16*C17/1000000 -> 1312.5 | D18: =D16*D17/1000000 -> 5197.5 | E18: =E16*E17/1000000 -> 14007.263 | F18: =F16*F17/1000000 -> 26193.581 | G18: =G16*G17/1000000 -> 41778.761
B19: Revenu épargne (M FCFA) | C19: =C18*Assumptions!$C$21 -> 19.6875 | D19: =D18*Assumptions!$C$21 -> 77.9625 | E19: =E18*Assumptions!$C$21 -> 210.10894 | F19: =F18*Assumptions!$C$21 -> 392.90371 | G19: =G18*Assumptions!$C$21 -> 626.68142
B21: Revenu micro-crédit (à partir de l'année 3)
B22: % épargnants utilisant le micro-crédit | C22: 0 | D22: 0 | E22: =Assumptions!$C$24 -> 0.12 | F22: =Assumptions!$C$24 -> 0.12 | G22: =Assumptions!$C$24 -> 0.12
B23: Nombre d'emprunteurs | C23: =C16*C22 -> 0 | D23: =D16*D22 -> 0 | E23: =E16*E22 -> 9261 | F23: =F16*F22 -> 15743.7 | G23: =G16*G22 -> 22828.365
B24: Encours de crédit moyen (FCFA) | C24: =Assumptions!$C$25 -> 80000 | D24: =Assumptions!$C$25 -> 80000 | E24: =Assumptions!$C$25 -> 80000 | F24: =Assumptions!$C$25 -> 80000 | G24: =Assumptions!$C$25 -> 80000
B25: Encours de crédit total (M FCFA) | C25: =C23*C24/1000000 -> 0 | D25: =D23*D24/1000000 -> 0 | E25: =E23*E24/1000000 -> 740.88 | F25: =F23*F24/1000000 -> 1259.496 | G25: =G23*G24/1000000 -> 1826.2692
B26: Revenu micro-crédit - marge nette d'intérêt (M FCFA) | C26: =C25*Assumptions!$C$26 -> 0 | D26: =D25*Assumptions!$C$26 -> 0 | E26: =E25*Assumptions!$C$26 -> 66.6792 | F26: =F25*Assumptions!$C$26 -> 113.35464 | G26: =G25*Assumptions!$C$26 -> 164.36423
B28: Chiffre d'affaires total
B29: Chiffre d'affaires total (M FCFA) | C29: =C12+C19+C26 -> 156.1875 | D29: =D12+D19+D26 -> 608.6745 | E29: =E12+E19+E26 -> 1681.0521 | F29: =F12+F19+F26 -> 3084.487 | G29: =G12+G19+G26 -> 4828.5517

Sheet P&L
B2: Compte de résultat (P&L) - KobaPay
B3: Toutes les valeurs sont en millions de FCFA (M FCFA).
C5: 2027F | D5: 2028F | E5: 2029F | F5: 2030F | G5: 2031F
B6: Chiffre d'affaires | C6: ='Revenue Build'!C29 -> 156.1875 | D6: ='Revenue Build'!D29 -> 608.6745 | E6: ='Revenue Build'!E29 -> 1681.0521 | F6: ='Revenue Build'!F29 -> 3084.487 | G6: ='Revenue Build'!G29 -> 4828.5517
B8: Charges opérationnelles
B9: Coût d'acquisition clients | C9: =-'Revenue Build'!C7*Assumptions!C58/1000000 -> -62.5 | D9: =-'Revenue Build'!D7*Assumptions!D58/1000000 -> -149.5 | E9: =-'Revenue Build'!E7*Assumptions!E58/1000000 -> -276.138 | F9: =-'Revenue Build'!F7*Assumptions!F58/1000000 -> -300.47623 | G9: =-'Revenue Build'!G7*Assumptions!G58/1000000 -> -302.10739
B10: Coûts techniques et hébergement | C10: =-C6*Assumptions!$C$31 -> -18.7425 | D10: =-D6*Assumptions!$C$31 -> -73.04094 | E10: =-E6*Assumptions!$C$31 -> -201.72625 | F10: =-F6*Assumptions!$C$31 -> -370.13844 | G10: =-G6*Assumptions!$C$31 -> -579.4262
B11: Masse salariale | C11: =-Assumptions!C35 -> -60 | D11: =-Assumptions!D35 -> -140 | E11: =-Assumptions!E35 -> -260 | F11: =-Assumptions!F35 -> -420 | G11: =-Assumptions!G35 -> -600
B12: Frais généraux et administratifs | C12: =-Assumptions!C36 -> -25 | D12: =-Assumptions!D36 -> -45 | E12: =-Assumptions!E36 -> -70 | F12: =-Assumptions!F36 -> -100 | G12: =-Assumptions!G36 -> -130
B13: Conformité réglementaire et licence | C13: =-Assumptions!C37 -> -40 | D13: =-Assumptions!D37 -> -30 | E13: =-Assumptions!E37 -> -30 | F13: =-Assumptions!F37 -> -35 | G13: =-Assumptions!G37 -> -35
B14: Total charges opérationnelles | C14: =SUM(C9:C13) -> -206.2425 | D14: =SUM(D9:D13) -> -437.54094 | E14: =SUM(E9:E13) -> -837.86425 | F14: =SUM(F9:F13) -> -1225.6147 | G14: =SUM(G9:G13) -> -1646.5336
B16: EBITDA | C16: =C6+C14 -> -50.055 | D16: =D6+D14 -> 171.13356 | E16: =E6+E14 -> 843.18784 | F16: =F6+F14 -> 1858.8723 | G16: =G6+G14 -> 3182.0181
B17: Marge d'EBITDA (%) | C17: =C16/C6 -> -0.32048019 | D17: =D16/D6 -> 0.28115776 | E17: =E16/E6 -> 0.50158341 | F17: =F16/F6 -> 0.60265202 | G17: =G16/G6 -> 0.65900052
B19: Amortissements et résultat
B20: Capex (pour mémoire) | C20: =Assumptions!C38 -> 20 | D20: =Assumptions!D38 -> 35 | E20: =Assumptions!E38 -> 55 | F20: =Assumptions!F38 -> 70 | G20: =Assumptions!G38 -> 85
B21: D&A (amortissement linéaire, base cumulée) | C21: =SUM($C$20:C20)/Assumptions!$C$39 -> 6.6666667 | D21: =SUM($C$20:D20)/Assumptions!$C$39 -> 18.333333 | E21: =SUM($C$20:E20)/Assumptions!$C$39 -> 36.666667 | F21: =SUM($C$20:F20)/Assumptions!$C$39 -> 60 | G21: =SUM($C$20:G20)/Assumptions!$C$39 -> 88.333333
B22: EBIT | C22: =C16-C21 -> -56.721667 | D22: =D16-D21 -> 152.80023 | E22: =E16-E21 -> 806.52117 | F22: =F16-F21 -> 1798.8723 | G22: =G16-G21 -> 3093.6847
B23: Produits financiers (intérêts sur trésorerie) | C23: ='Cash Flow'!C17*Assumptions!$C$41 -> 0 | D23: ='Cash Flow'!D17*Assumptions!$C$41 -> 9.5650073 | E23: ='Cash Flow'!E17*Assumptions!$C$41 -> 12.310987 | F23: ='Cash Flow'!F17*Assumptions!$C$41 -> 29.21957 | G23: ='Cash Flow'!G17*Assumptions!$C$41 -> 68.788546
B24: Résultat avant impôt (EBT) | C24: =C22+C23 -> -56.721667 | D24: =D22+D23 -> 162.36523 | E24: =E22+E23 -> 818.83216 | F24: =F22+F23 -> 1828.0919 | G24: =G22+G23 -> 3162.4733
B25: Impôt sur les sociétés | C25: =-MAX(C24,0)*Assumptions!$C$32 -> 0 | D25: =-MAX(D24,0)*Assumptions!$C$32 -> -40.591308 | E25: =-MAX(E24,0)*Assumptions!$C$32 -> -204.70804 | F25: =-MAX(F24,0)*Assumptions!$C$32 -> -457.02297 | G25: =-MAX(G24,0)*Assumptions!$C$32 -> -790.61832
B26: Résultat net | C26: =C24+C25 -> -56.721667 | D26: =D24+D25 -> 121.77393 | E26: =E24+E25 -> 614.12412 | F26: =F24+F25 -> 1371.0689 | G26: =G24+G25 -> 2371.855

Sheet Cash Flow
B2: Trésorerie et financement - KobaPay
B3: Toutes les valeurs sont en millions de FCFA (M FCFA), converties au taux de change fixe FCFA/EUR.
C5: 2027F | D5: 2028F | E5: 2029F | F5: 2030F | G5: 2031F
B6: Résultat net | C6: ='P&L'!C26 -> -56.721667 | D6: ='P&L'!D26 -> 121.77393 | E6: ='P&L'!E26 -> 614.12412 | F6: ='P&L'!F26 -> 1371.0689 | G6: ='P&L'!G26 -> 2371.855
B7: + D&A (charge non monétaire) | C7: ='P&L'!C21 -> 6.6666667 | D7: ='P&L'!D21 -> 18.333333 | E7: ='P&L'!E21 -> 36.666667 | F7: ='P&L'!F21 -> 60 | G7: ='P&L'!G21 -> 88.333333
B8: - Capex | C8: =-Assumptions!C38 -> -20 | D8: =-Assumptions!D38 -> -35 | E8: =-Assumptions!E38 -> -55 | F8: =-Assumptions!F38 -> -70 | G8: =-Assumptions!G38 -> -85
B9: - Variation du BFR | C9: =-'P&L'!C6*Assumptions!$C$40 -> -4.685625 | D9: =-('P&L'!D6-'P&L'!C6)*Assumptions!$C$40 -> -13.57461 | E9: =-('P&L'!E6-'P&L'!D6)*Assumptions!$C$40 -> -32.171328 | F9: =-('P&L'!F6-'P&L'!E6)*Assumptions!$C$40 -> -42.103046 | G9: =-('P&L'!G6-'P&L'!F6)*Assumptions!$C$40 -> -52.321941
B10: Flux de trésorerie d'exploitation et d'investissement | C10: =SUM(C6:C9) -> -74.740625 | D10: =SUM(D6:D9) -> 91.532649 | E10: =SUM(E6:E9) -> 563.61946 | F10: =SUM(F6:F9) -> 1318.9659 | G10: =SUM(G6:G9) -> 2322.8664
B12: Financement
B13: + Apport initial des fondateurs (M FCFA) | C13: =Assumptions!$C$44*Assumptions!$C$47/1000000 -> 32.79785 | D13: 0 | E13: 0 | F13: 0 | G13: 0
B14: + Levée de fonds - seed round (M FCFA) | C14: =Assumptions!$C$45*Assumptions!$C$47/1000000 -> 360.77635 | D14: 0 | E14: 0 | F14: 0 | G14: 0
B15: Flux net de trésorerie de la période | C15: =C10+C13+C14 -> 318.83357 | D15: =D10+D13+D14 -> 91.532649 | E15: =E10+E13+E14 -> 563.61946 | F15: =F10+F13+F14 -> 1318.9659 | G15: =G10+G13+G14 -> 2322.8664
B17: Trésorerie d'ouverture | C17: 0 | D17: =C18 -> 318.83357 | E17: =D18 -> 410.36622 | F17: =E18 -> 973.98568 | G17: =F18 -> 2292.9515
B18: Trésorerie de clôture | C18: =C17+C15 -> 318.83357 | D18: =D17+D15 -> 410.36622 | E18: =E17+E15 -> 973.98568 | F18: =F17+F15 -> 2292.9515 | G18: =G17+G15 -> 4615.8179
B20: Contrôle : trésorerie toujours positive ? | C20: =IF(C18>=0,"OK","ALERTE") -> OK | D20: =IF(D18>=0,"OK","ALERTE") -> OK | E20: =IF(E18>=0,"OK","ALERTE") -> OK | F20: =IF(F18>=0,"OK","ALERTE") -> OK | G20: =IF(G18>=0,"OK","ALERTE") -> OK
B22: Lecture : l'apport des fondateurs et la levée de fonds (seed round) sont injectés en année 1 (2027F), convertis en FCFA au taux de change fixe. La trésorerie de clôture mesure le runway du financement face au rythme de consommation de cash (burn) avant que KobaPay n'atteigne la rentabilité.

Sheet Funding & Cap Table
B2: Levée de fonds et table de capitalisation - KobaPay
B3: Valeurs en euros (EUR), sauf mention contraire.
B5: Levée de fonds (seed round)
B6: Montant levé | C6: =Assumptions!$C$45 -> 550000
B7: Valorisation pre-money | C7: =Assumptions!$C$46 -> 2450000
B8: Valorisation post-money | C8: =C7+C6 -> 3000000
B9: % cédé aux nouveaux investisseurs | C9: =C6/C8 -> 0.18333333
B10: Pool ESOP (% post-money) | C10: =Assumptions!$C$48 -> 0.1
B11: % conservé par les fondateurs | C11: =1-C9-C10 -> 0.71666667
B13: Cap table (post-seed)
B14: Actionnaire | C14: % du capital
B15: Fondateurs | C15: =C11 -> 0.71666667
B16: Investisseurs seed | C16: =C9 -> 0.18333333
B17: Pool ESOP | C17: =C10 -> 0.1
B18: Total (contrôle) | C18: =SUM(C15:C17) -> 1
B20: Utilisation des fonds
B21: Poste | C21: % de la levée | D21: Montant (EUR)
B22: Produit et technologie | C22: =Assumptions!$C$51 -> 0.35 | D22: =C22*$C$6 -> 192500
B23: Acquisition et marketing | C23: =Assumptions!$C$52 -> 0.3 | D23: =C23*$C$6 -> 165000
B24: Recrutement équipe clé | C24: =Assumptions!$C$53 -> 0.25 | D24: =C24*$C$6 -> 137500
B25: Conformité réglementaire et licence EME | C25: =Assumptions!$C$54 -> 0.1 | D25: =C25*$C$6 -> 55000
B26: Total (contrôle) | C26: =SUM(C22:C25) -> 1 | D26: =SUM(D22:D25) -> 550000

Sheet Dashboard
B2: Dashboard - KobaPay
B3: Toutes les valeurs sont en millions de FCFA (M FCFA), sauf mention contraire.
B5: Indicateurs clés
C6: 2027F | D6: 2028F | E6: 2029F | F6: 2030F | G6: 2031F
B7: Chiffre d'affaires (M FCFA) | C7: ='Revenue Build'!C29 -> 156.1875 | D7: ='Revenue Build'!D29 -> 608.6745 | E7: ='Revenue Build'!E29 -> 1681.0521 | F7: ='Revenue Build'!F29 -> 3084.487 | G7: ='Revenue Build'!G29 -> 4828.5517
B8: Marge d'EBITDA (%) | C8: ='P&L'!C17 -> -0.32048019 | D8: ='P&L'!D17 -> 0.28115776 | E8: ='P&L'!E17 -> 0.50158341 | F8: ='P&L'!F17 -> 0.60265202 | G8: ='P&L'!G17 -> 0.65900052
B9: Trésorerie de clôture (M FCFA) | C9: ='Cash Flow'!C18 -> 318.83357 | D9: ='Cash Flow'!D18 -> 410.36622 | E9: ='Cash Flow'!E18 -> 973.98568 | F9: ='Cash Flow'!F18 -> 2292.9515 | G9: ='Cash Flow'!G18 -> 4615.8179

Sheet Checks
B2: Contrôles de cohérence - KobaPay
B5: Contrôle | C5: Résultat | D5: Statut
B6: Chiffre d'affaires : Revenue Build = P&L (année 5) | C6: ='Revenue Build'!G29-'P&L'!G6 -> 0 | D6: =IF(ABS(C6)<0.01,"OK","ERREUR") -> OK
B7: Cap table : somme = 100% | C7: ='Funding & Cap Table'!C18-1 -> 0 | D7: =IF(ABS(C7)<0.0001,"OK","ERREUR") -> OK
B8: Utilisation des fonds (table) : somme = 100% | C8: ='Funding & Cap Table'!C26-1 -> 0 | D8: =IF(ABS(C8)<0.0001,"OK","ERREUR") -> OK
B9: Utilisation des fonds (Assumptions) : somme = 100% | C9: =Assumptions!C55-1 -> 0 | D9: =IF(ABS(C9)<0.0001,"OK","ERREUR") -> OK
B10: Résultat net P&L = Résultat net Cash Flow (année 5) | C10: ='P&L'!G26-'Cash Flow'!G6 -> 0 | D10: =IF(ABS(C10)<0.01,"OK","ERREUR") -> OK
B11: Trésorerie jamais négative sur les 5 ans | C11: =COUNTIF('Cash Flow'!C20:G20,"ALERTE") -> 0 | D11: =IF(C11=0,"OK","ALERTE") -> OK
