Workbook

Sheet Cover
B2: Modèle intégré 3 états + DCF - Fnac Darty (EPA : FNAC)
B3: Exercice de formation - Yvann Ahoure
B4: Toutes les valeurs sont en millions d'euros (M€), sauf mention contraire.
B6: Objectif du modèle
B7: Le modèle intègre 3 exercices réels (FY2023A-FY2025A) pour le compte de résultat, des schedules dédiées (fonds de roulement, immobilisations/amortissements, dette avec remboursement programmé et sweep de trésorerie excédentaire), un DCF alimenté directement par les projections du modèle, une grille de sensibilité et un dashboard de graphiques. Objectif : montrer la chaîne complète historique réel -> modèle 3 états -> valorisation, pas seulement un modèle 3 états isolé.
B9: Avertissement sur la nature des données
B10: Le chiffre d'affaires, l'EBIT (résultat opérationnel courant) et le résultat net des 3 derniers exercices (FY2023A-FY2025A), ainsi que la trésorerie, la dette financière brute, les totaux de bilan FY2025A, l'EBITDA FY2025A, le cours de bourse, le nombre d'actions, le bêta et le coupon obligataire sont des chiffres réels publiés par Fnac Darty ou issus de sources de marché (voir Sources ci-dessous et le détail dans l'onglet Assumptions). La répartition détaillée du bilan d'ouverture (créances, stocks, immobilisations hors montant total, dettes fournisseurs, dettes locatives, autres passifs) n'est pas publiée à ce niveau de détail : elle est une reconstruction personnelle plausible, recalée pour respecter à la fois les totaux de bilan réels et les deux nouvelles ancres réelles (trésorerie et dette financière brute). Les hypothèses de projection 2026-2030 (croissance, marges, délais de BFR, capex, seuil de trésorerie, prime de risque, croissance terminale) sont des estimations personnelles, clairement identifiées dans Assumptions.
B13: Point de vigilance méthodologique : rupture de périmètre Unieuro
B14: Fnac Darty a acquis Unieuro (Italie) en novembre 2024. Le chiffre d'affaires FY2023A (7 875 M€) est sur un périmètre 100% organique ; FY2024A (8 253 M€) inclut environ 2 mois d'Unieuro ; FY2025A (10 330 M€) inclut Unieuro en année pleine. La hausse FY2024A -> FY2025A n'est donc pas une croissance organique comparable, mais tire largement son origine du changement de périmètre - signalé explicitement plutôt que lissé.
B17: Sommaire
B18: Assumptions | C18: Bilan d'ouverture, hypothèses opérationnelles, données de marché et hypothèses de valorisation (WACC)
B19: Working Capital Schedule | C19: Schedule détaillée du besoin en fonds de roulement (créances, stocks, fournisseurs)
B20: PP&E Schedule | C20: Rollforward des immobilisations (capex - amortissements)
B21: Debt Schedule | C21: Échéancier de dette : remboursement programmé + sweep de trésorerie excédentaire
B22: Income Statement | C22: Compte de résultat : 3 exercices réels (FY2023A-FY2025A) + projection 5 ans
B23: Balance Sheet | C23: Bilan : FY2025A (réel + reconstruction) + projection 5 ans
B24: Cash Flow | C24: Tableau de flux de trésorerie, FY2026F-FY2030F
B25: DCF | C25: Valorisation DCF : WACC (CAPM), FCFF, valeur d'entreprise, valeur par action implicite
B26: Sensitivity | C26: Grille de sensibilité WACC x croissance terminale sur la valeur par action
B27: Dashboard | C27: Graphiques de synthèse (compte de résultat, flux de trésorerie, valorisation)
B28: Checks | C28: Contrôles de cohérence du modèle
B30: Sources (données réelles)
B31: - Communiqué de résultats annuels Fnac Darty FY2024 (26/02/2025, fnacdarty.com) : CA FY2023 et FY2024 tels que publiés, capex brut FY2023-FY2024.
B32: - Communiqué préliminaire de résultats annuels FY2025 (26/01/2026, globenewswire.com) et présentation FY2025 (fnacdarty.com, 25/02/2026) : CA, EBIT, résultat net, EBITDA, D&A, charge financière, trésorerie et dette financière brute FY2025, chiffres FY2024 retraités (périmètre Unieuro en année pleine).
B33: - Communiqué de pricing de l'émission obligataire senior (mars 2025, fnacdarty.com) : montant 300 M€, coupon fixe 4,75 %, maturité avril 2032.
B34: - stockanalysis.com (cours de bourse, actions en circulation, bêta - 12/10/2026).
B35: - tradingeconomics.com (taux de l'OAT France 10 ans - 12/10/2026).

Sheet Assumptions
B2: Hypothèses
B3: Toutes les valeurs sont en millions d'euros (M€), sauf mention contraire.
B5: BILAN D'OUVERTURE FY2025A (ancres réelles + reconstruction complémentaire)
B6: Trésorerie | C6: 1104 | E6: Réel - présentation des résultats annuels FY2025 (fnacdarty.com, 25/02/2026).
B7: Créances clients | C7: 349 | E7: Reconstruction personnelle (voir méthode en E19).
B8: Stocks | C8: 1333 | E8: Reconstruction personnelle (voir méthode en E19).
B9: Immobilisations (PP&E + droits d'usage IFRS16) | C9: 3493 | E9: Reconstruction personnelle (voir méthode en E19).
B10: Goodwill et incorporels | C10: 2264 | E10: Reconstruction personnelle (voir méthode en E19).
B11: Dettes fournisseurs | C11: 1297 | E11: Reconstruction personnelle (voir méthode en E19).
B12: Dettes locatives (IFRS16) | C12: 3135 | E12: Reconstruction personnelle (voir méthode en E19).
B13: Dette financière brute (hors IFRS16) | C13: 958 | E13: Réelle - présentation des résultats annuels FY2025 (fnacdarty.com, 25/02/2026).
B14: Autres passifs (provisions, impôts, divers) | C14: 1577 | E14: Reconstruction personnelle (voir méthode en E19).
B15: Capitaux propres | C15: 1576 | E15: Réel, publié (communiqué FY2025).
B17: Contrôle : actif total reconstitué | C17: =SUM(C6:C10) -> 8543
B18: Contrôle : passif + capitaux propres reconstitués | C18: =SUM(C11:C15) -> 8543
B19: Écart (doit être nul) | C19: =C17-C18 -> 0 | E19: Méthode de reconstruction : seuls le total actif (8 543 M€), le total capitaux propres (1 576 M€), la trésorerie (1 104 M€, réelle) et la dette financière brute (958 M€, réelle) sont des ancres fixes. Les 4 autres postes d'actif et les 3 autres postes de passif sont répartis proportionnellement à une estimation plausible de structure de bilan retail, de façon à ce que les totaux réels soient respectés exactement.
B21: HYPOTHÈSES OPÉRATIONNELLES 2026-2030 (personnelles)
B22: Croissance du chiffre d'affaires (%/an) | C22: 0.02 | E22: Hypothèse personnelle (croissance modérée, cohérente avec un secteur retail mature).
B23: Marge d'EBIT (% du CA) | C23: 0.02 | E23: Hypothèse personnelle, alignée sur la marge d'EBIT réelle FY2025A (203/10 330 = 2,0 %).
B24: D&A (% du CA) | C24: ='Income Statement'!E8/'Income Statement'!E6 -> 0.044917715 | E24: Calculé à partir du D&A réel FY2025A (464 M€, présentation FY2025) rapporté au CA réel FY2025A.
B25: Capex (% du CA) | C25: 0.025 | E25: Hypothèse personnelle. Pour comparaison, le capex réel publié s'est établi entre 122 et 176 M€ selon les exercices et la base (brut/net de cessions), voir Sources ; l'hypothèse se situe dans cet ordre de grandeur.
B26: Délai clients (jours de CA) | C26: =C7/'Income Statement'!$E$6*365 -> 12.331559 | E26: Calculé sur le bilan d'ouverture reconstitué (créances / CA réel x 365) : la formule ancre exactement le premier exercice prévisionnel sur le bilan d'ouverture, sans à-coup de BFR.
B27: Délai stocks (jours de CA) | C27: =C8/'Income Statement'!$E$6*365 -> 47.100194 | E27: Calculé sur le bilan d'ouverture reconstitué (stocks / CA réel x 365).
B28: Délai fournisseurs (jours de CA) | C28: =C11/'Income Statement'!$E$6*365 -> 45.82817 | E28: Calculé sur le bilan d'ouverture reconstitué (fournisseurs / CA réel x 365).
B29: Taux d'IS | C29: 0.25 | E29: Taux normal de l'impôt sur les sociétés en France.
B30: Taux d'intérêt sur la dette financière | C30: 0.045 | E30: Hypothèse personnelle, proche du coût de la dette avant impôt réel (obligation senior, 4,75 %) ; voir C52.
B31: Taux d'intérêt implicite sur les dettes locatives | C31: 0.03 | E31: Hypothèse personnelle.
B32: Amortissement programmé de la dette financière (M€/an) | C32: 100 | E32: Hypothèse de simplification. La dette réelle est une obligation senior in fine (300 M€, échéance avril 2032) : le modèle ne cherche pas à répliquer ce profil bullet exact mais illustre la mécanique d'un échéancier de dette avec amortissement + sweep (voir Debt Schedule).
B33: Seuil de trésorerie minimum cible (M€) | C33: 400 | E33: Hypothèse personnelle : au-delà de ce seuil, la trésorerie excédentaire de l'exercice précédent sert au remboursement anticipé de la dette (voir Debt Schedule).
B34: Taux de sweep de la trésorerie excédentaire (%) | C34: 0.5 | E34: Hypothèse personnelle : 50 % de l'excédent de trésorerie disponible est affecté au remboursement anticipé, le solde reste disponible pour d'autres usages.
B35: Taux de distribution de dividendes (% du RN, si positif) | C35: 0.3 | E35: Hypothèse personnelle.
B37: DONNÉES RÉELLES DE MARCHÉ ET DE DETTE (base de la valorisation)
B38: Cours de bourse Fnac Darty (EPA : FNAC) | C38: 34.4 | E38: Réel - stockanalysis.com, clôture du 12/10/2026.
B39: Actions en circulation (millions) | C39: 29.37 | E39: Réel - stockanalysis.com, au 14/09/2026 (dernier chiffre disponible).
B40: Capitalisation boursière (M€) | C40: =C38*C39 -> 1010.328
B41: Dette financière brute hors IFRS16 (= Assumptions C13) | C41: =C13 -> 958
B42: Trésorerie (= Assumptions C6) | C42: =C6 -> 1104
B43: Dette nette hors IFRS16 (négatif = position de cash net) | C43: =C41-C42 -> -146 | E43: 958 - 1 104 = -146 M€ : Fnac Darty est en position de cash net hors IFRS16 à fin FY2025, et non en dette nette. Point clarifié par cette recherche (un résidu ambigu sur ce point avait été signalé dans le projet 4 Transaction Services DD).
B44: EBITDA FY2025A réel | C44: 667 | E44: Réel - présentation des résultats annuels FY2025 (périmètre Unieuro année pleine).
B45: Valeur d'entreprise réelle implicite (M€) | C45: =C40+C43 -> 864.328
...

Sheet Working Capital Schedule
B2: Schedule du besoin en fonds de roulement (BFR)
B3: Toutes les valeurs sont en millions d'euros (M€), sauf mention contraire. Historique non reconstitué : seule FY2025A (colonne E) sert d'ancre.
C5: FY2023A | D5: FY2024A | E5: FY2025A | F5: FY2026F | G5: FY2027F | H5: FY2028F | I5: FY2029F | J5: FY2030F
B6: HYPOTHÈSES DE DÉLAIS (jours, référence Assumptions)
B7: Délai clients (jours de CA) | F7: =Assumptions!$C$26 -> 12.331559 | G7: =Assumptions!$C$26 -> 12.331559 | H7: =Assumptions!$C$26 -> 12.331559 | I7: =Assumptions!$C$26 -> 12.331559 | J7: =Assumptions!$C$26 -> 12.331559
B8: Délai stocks (jours de CA) | F8: =Assumptions!$C$27 -> 47.100194 | G8: =Assumptions!$C$27 -> 47.100194 | H8: =Assumptions!$C$27 -> 47.100194 | I8: =Assumptions!$C$27 -> 47.100194 | J8: =Assumptions!$C$27 -> 47.100194
B9: Délai fournisseurs (jours de CA) | F9: =Assumptions!$C$28 -> 45.82817 | G9: =Assumptions!$C$28 -> 45.82817 | H9: =Assumptions!$C$28 -> 45.82817 | I9: =Assumptions!$C$28 -> 45.82817 | J9: =Assumptions!$C$28 -> 45.82817
B11: MONTANT PAR JOUR
B12: Chiffre d'affaires par jour (CA / 365) | F12: ='Income Statement'!F6/365 -> 28.867397 | G12: ='Income Statement'!G6/365 -> 29.444745 | H12: ='Income Statement'!H6/365 -> 30.03364 | I12: ='Income Statement'!I6/365 -> 30.634313 | J12: ='Income Statement'!J6/365 -> 31.246999
B14: SOLDES DE BFR
B15: Créances clients | E15: =Assumptions!$C$7 -> 349 | F15: =F7*F12 -> 355.98 | G15: =G7*G12 -> 363.0996 | H15: =H7*H12 -> 370.36159 | I15: =I7*I12 -> 377.76882 | J15: =J7*J12 -> 385.3242
B16: Stocks | E16: =Assumptions!$C$8 -> 1333 | F16: =F8*F12 -> 1359.66 | G16: =G8*G12 -> 1386.8532 | H16: =H8*H12 -> 1414.5903 | I16: =I8*I12 -> 1442.8821 | J16: =J8*J12 -> 1471.7397
B17: Dettes fournisseurs | E17: =Assumptions!$C$11 -> 1297 | F17: =F9*F12 -> 1322.94 | G17: =G9*G12 -> 1349.3988 | H17: =H9*H12 -> 1376.3868 | I17: =I9*I12 -> 1403.9145 | J17: =J9*J12 -> 1431.9928
B18: BFR net (créances + stocks - fournisseurs) | E18: =E15+E16-E17 -> 385 | F18: =F15+F16-F17 -> 392.7 | G18: =G15+G16-G17 -> 400.554 | H18: =H15+H16-H17 -> 408.56508 | I18: =I15+I16-I17 -> 416.73638 | J18: =J15+J16-J17 -> 425.07111
B20: VARIATION DE BFR (impact trésorerie, flux de financement de l'exploitation)
B21: - Variation des créances clients (impact cash) | F21: =-(F15-E15) -> -6.98 | G21: =-(G15-F15) -> -7.1196 | H21: =-(H15-G15) -> -7.261992 | I21: =-(I15-H15) -> -7.4072318 | J21: =-(J15-I15) -> -7.5553765
B22: - Variation des stocks (impact cash) | F22: =-(F16-E16) -> -26.66 | G22: =-(G16-F16) -> -27.1932 | H22: =-(H16-G16) -> -27.737064 | I22: =-(I16-H16) -> -28.291805 | J22: =-(J16-I16) -> -28.857641
B23: + Variation des dettes fournisseurs (impact cash) | F23: =F17-E17 -> 25.94 | G23: =G17-F17 -> 26.4588 | H23: =H17-G17 -> 26.987976 | I23: =I17-H17 -> 27.527736 | J23: =J17-I17 -> 28.07829
B24: -> Impact net de la variation de BFR sur la trésorerie | F24: =SUM(F21:F23) -> -7.7 | G24: =SUM(G21:G23) -> -7.854 | H24: =SUM(H21:H23) -> -8.01108 | I24: =SUM(I21:I23) -> -8.1713016 | J24: =SUM(J21:J23) -> -8.3347276
B26: Simplification assumée : les délais clients et fournisseurs sont calculés sur une base chiffre d'affaires (et non coût des ventes), faute de décomposition publique du coût des ventes à ce niveau de détail.

Sheet PP&E Schedule
B2: Schedule des immobilisations et amortissements
B3: Toutes les valeurs sont en millions d'euros (M€). Rollforward PP&E + droits d'usage IFRS16.
C5: FY2023A | D5: FY2024A | E5: FY2025A | F5: FY2026F | G5: FY2027F | H5: FY2028F | I5: FY2029F | J5: FY2030F
B6: ROLLFORWARD DES IMMOBILISATIONS
B7: Immobilisations en début de période | E7: =Assumptions!$C$9 -> 3493 | F7: =E10 -> 3493 | G7: =F10 -> 3283.135 | H7: =G10 -> 3069.0727 | I7: =H10 -> 2850.7292 | J7: =I10 -> 2628.0187
B8: + Investissements (capex) | F8: ='Income Statement'!F6*Assumptions!$C$25 -> 263.415 | G8: ='Income Statement'!G6*Assumptions!$C$25 -> 268.6833 | H8: ='Income Statement'!H6*Assumptions!$C$25 -> 274.05697 | I8: ='Income Statement'!I6*Assumptions!$C$25 -> 279.53811 | J8: ='Income Statement'!J6*Assumptions!$C$25 -> 285.12887
B9: - Dotations aux amortissements (D&A) | F9: =-'Income Statement'!F8 -> -473.28 | G9: =-'Income Statement'!G8 -> -482.7456 | H9: =-'Income Statement'!H8 -> -492.40051 | I9: =-'Income Statement'!I8 -> -502.24852 | J9: =-'Income Statement'!J8 -> -512.29349
B10: Immobilisations en fin de période | E10: =E7 -> 3493 | F10: =F7+F8+F9 -> 3283.135 | G10: =G7+G8+G9 -> 3069.0727 | H10: =H7+H8+H9 -> 2850.7292 | I10: =I7+I8+I9 -> 2628.0187 | J10: =J7+J8+J9 -> 2400.8541
B12: Le capex réel publié par Fnac Darty varie selon la base retenue (brut avant cessions : 122-176 M€ sur FY2023-FY2025 ; net de cessions : 56-176 M€ selon l'exercice - voir Sources, Cover). L'hypothèse de 2,5 % du CA se situe dans cet ordre de grandeur sans chercher à répliquer un exercice particulier.
B13: Point de vigilance : le D&A (4,5 % du CA, cohérent avec le réel FY2025A qui inclut l'amortissement des droits d'usage IFRS16) dépasse le capex (2,5 % du CA), ce qui fait mécaniquement diminuer la valeur nette des immobilisations sur l'horizon de projection. Ce n'est pas nécessairement une erreur de modèle (une partie du D&A correspond aux droits d'usage IFRS16, dont le coût cash passe par le remboursement des dettes locatives et non par du capex), mais cet écart gonfle le FCFF du DCF - voir la note correspondante dans l'onglet DCF.

Sheet Debt Schedule
B2: Schedule de dette : remboursement programmé + sweep de trésorerie
B3: Toutes les valeurs sont en millions d'euros (M€). Porte sur la dette financière brute hors IFRS16.
C5: FY2023A | D5: FY2024A | E5: FY2025A | F5: FY2026F | G5: FY2027F | H5: FY2028F | I5: FY2029F | J5: FY2030F
B6: La dette réelle de Fnac Darty est une obligation senior de 300 M€, remboursable in fine en avril 2032 (coupon fixe 4,75 %). Le modèle simplifie volontairement en un amortissement linéaire hypothétique + un mécanisme de remboursement anticipé (cash sweep) non circulaire, pour illustrer la mécanique d'un échéancier de dette - ce n'est pas une prévision du remboursement réel de cette obligation.
B7: DETTE FINANCIÈRE BRUTE
B8: Dette en début de période | E8: =Assumptions!$C$13 -> 958 | F8: =E14 -> 958 | G8: =F14 -> 506 | H8: =G14 -> 159.60485 | I8: =H14 -> 0 | J8: =I14 -> 0
B9: - Amortissement programmé | F9: =-MIN(F8,Assumptions!$C$32) -> -100 | G9: =-MIN(G8,Assumptions!$C$32) -> -100 | H9: =-MIN(H8,Assumptions!$C$32) -> -100 | I9: =-MIN(I8,Assumptions!$C$32) -> 0 | J9: =-MIN(J8,Assumptions!$C$32) -> 0
B10: Trésorerie de clôture de l'exercice précédent (référence) | E10: =Assumptions!$C$6 -> 1104 | F10: ='Balance Sheet'!E7 -> 1104 | G10: ='Balance Sheet'!F7 -> 892.7903 | H10: ='Balance Sheet'!G7 -> 804.11994 | I10: ='Balance Sheet'!H7 -> 916.80456 | J10: ='Balance Sheet'!I7 -> 1199.3734
B11: Seuil de trésorerie minimum cible (réf. Assumptions) | F11: =Assumptions!$C$33 -> 400 | G11: =Assumptions!$C$33 -> 400 | H11: =Assumptions!$C$33 -> 400 | I11: =Assumptions!$C$33 -> 400 | J11: =Assumptions!$C$33 -> 400
B12: Excédent de trésorerie disponible (si positif) | F12: =MAX(F10-F11,0) -> 704 | G12: =MAX(G10-G11,0) -> 492.7903 | H12: =MAX(H10-H11,0) -> 404.11994 | I12: =MAX(I10-I11,0) -> 516.80456 | J12: =MAX(J10-J11,0) -> 799.37343
B13: - Remboursement anticipé (sweep) | F13: =-MIN(F12*Assumptions!$C$34,MAX(F8+F9,0)) -> -352 | G13: =-MIN(G12*Assumptions!$C$34,MAX(G8+G9,0)) -> -246.39515 | H13: =-MIN(H12*Assumptions!$C$34,MAX(H8+H9,0)) -> -59.60485 | I13: =-MIN(I12*Assumptions!$C$34,MAX(I8+I9,0)) -> 0 | J13: =-MIN(J12*Assumptions!$C$34,MAX(J8+J9,0)) -> 0
B14: Dette en fin de période | E14: =E8 -> 958 | F14: =MAX(F8+F9+F13,0) -> 506 | G14: =MAX(G8+G9+G13,0) -> 159.60485 | H14: =MAX(H8+H9+H13,0) -> 0 | I14: =MAX(I8+I9+I13,0) -> 0 | J14: =MAX(J8+J9+J13,0) -> 0
B15: Variation totale de la dette (amortissement + sweep) | F15: =F9+F13 -> -452 | G15: =G9+G13 -> -346.39515 | H15: =H9+H13 -> -159.60485 | I15: =I9+I13 -> 0 | J15: =J9+J13 -> 0
B17: CHARGE D'INTÉRÊT (sur dette en début de période, non circulaire)
B18: Charge d'intérêt sur la dette financière | F18: =-F8*Assumptions!$C$30 -> -43.11 | G18: =-G8*Assumptions!$C$30 -> -22.77 | H18: =-H8*Assumptions!$C$30 -> -7.1822183 | I18: =-I8*Assumptions!$C$30 -> 0 | J18: =-J8*Assumptions!$C$30 -> 0

Sheet Income Statement
B2: Compte de résultat
B3: Toutes les valeurs sont en millions d'euros (M€), sauf mention contraire.
C5: FY2023A | D5: FY2024A | E5: FY2025A | F5: FY2026F | G5: FY2027F | H5: FY2028F | I5: FY2029F | J5: FY2030F
B6: Chiffre d'affaires | C6: 7875 | D6: 8253 | E6: 10330 | F6: =E6*(1+Assumptions!$C$22) -> 10536.6 | G6: =F6*(1+Assumptions!$C$22) -> 10747.332 | H6: =G6*(1+Assumptions!$C$22) -> 10962.279 | I6: =H6*(1+Assumptions!$C$22) -> 11181.524 | J6: =I6*(1+Assumptions!$C$22) -> 11405.155
B7: EBIT (résultat opérationnel courant) | C7: 171 | D7: 189 | E7: 203 | F7: =F6*Assumptions!$C$23 -> 210.732 | G7: =G6*Assumptions!$C$23 -> 214.94664 | H7: =H6*Assumptions!$C$23 -> 219.24557 | I7: =I6*Assumptions!$C$23 -> 223.63048 | J7: =J6*Assumptions!$C$23 -> 228.10309
B8: D&A (mémo, inclus dans l'EBIT) | C8: =C6*0.034 -> 267.75 | D8: =D6*0.034 -> 280.602 | E8: 464 | F8: =F6*Assumptions!$C$24 -> 473.28 | G8: =G6*Assumptions!$C$24 -> 482.7456 | H8: =H6*Assumptions!$C$24 -> 492.40051 | I8: =I6*Assumptions!$C$24 -> 502.24852 | J8: =J6*Assumptions!$C$24 -> 512.29349
B9: EBITDA (EBIT + D&A) | C9: =C7+C8 -> 438.75 | D9: =D7+D8 -> 469.602 | E9: =E7+E8 -> 667 | F9: =F7+F8 -> 684.012 | G9: =G7+G8 -> 697.69224 | H9: =H7+H8 -> 711.64608 | I9: =I7+I8 -> 725.87901 | J9: =J7+J8 -> 740.39659
B11: BRIDGE EBT -> RÉSULTAT NET (prévisions ; voir note en ligne 16 pour l'historique)
B12: Charge d'intérêt (dette financière + dettes locatives) | E12: -118 | F12: ='Debt Schedule'!F18-'Balance Sheet'!E16*Assumptions!$C$31 -> -137.16 | G12: ='Debt Schedule'!G18-'Balance Sheet'!F16*Assumptions!$C$31 -> -116.82 | H12: ='Debt Schedule'!H18-'Balance Sheet'!G16*Assumptions!$C$31 -> -101.23222 | I12: ='Debt Schedule'!I18-'Balance Sheet'!H16*Assumptions!$C$31 -> -94.05 | J12: ='Debt Schedule'!J18-'Balance Sheet'!I16*Assumptions!$C$31 -> -94.05
B13: Résultat avant impôt (EBT) | E13: =E7-E12 -> 321 | F13: =F7+F12 -> 73.572 | G13: =G7+G12 -> 98.12664 | H13: =H7+H12 -> 118.01335 | I13: =I7+I12 -> 129.58048 | J13: =J7+J12 -> 134.05309
B14: Impôt (= MAX(EBT,0) x taux d'IS) | F14: =MAX(F13,0)*Assumptions!$C$29 -> 18.393 | G14: =MAX(G13,0)*Assumptions!$C$29 -> 24.53166 | H14: =MAX(H13,0)*Assumptions!$C$29 -> 29.503339 | I14: =MAX(I13,0)*Assumptions!$C$29 -> 32.395121 | J14: =MAX(J13,0)*Assumptions!$C$29 -> 33.513273
B15: Résultat net | C15: 50 | D15: 36 | E15: -146 | F15: =F13-F14 -> 55.179 | G15: =G13-G14 -> 73.59498 | H15: =H13-H14 -> 88.510016 | I15: =I13-I14 -> 97.185363 | J15: =J13-J14 -> 100.53982
B16: FY2023A/FY2024A : résultat net publié (part du Groupe), incluant des éléments non récurrents et activités cédées non détaillés ici. FY2025A : résultat net publié, tiré par 183 M€ de dépréciations non récurrentes - le pont détaillé EBIT -> résultat net FY2025A (dépréciations, résidu non documenté publiquement) est traité dans le projet 4 (Transaction Services DD). E13 (85 M€) est un EBT analytique avant éléments non récurrents, fourni à titre indicatif - il ne se reconcilie pas avec le résultat net publié (-146 M€) pour cette raison, et aucun impôt n'est calculé dessus (ligne 14 laissée vide en E).
B18: Dividendes versés | F18: =MAX(F15,0)*Assumptions!$C$35 -> 16.5537 | G18: =MAX(G15,0)*Assumptions!$C$35 -> 22.078494 | H18: =MAX(H15,0)*Assumptions!$C$35 -> 26.553005 | I18: =MAX(I15,0)*Assumptions!$C$35 -> 29.155609 | J18: =MAX(J15,0)*Assumptions!$C$35 -> 30.161946
B20: RATIOS ET ANALYSE
B21: Croissance du CA (%) | D21: =D6/C6-1 -> 0.048 | E21: =E6/D6-1 -> 0.25166606 | F21: =F6/E6-1 -> 0.02 | G21: =G6/F6-1 -> 0.02 | H21: =H6/G6-1 -> 0.02 | I21: =I6/H6-1 -> 0.02 | J21: =J6/I6-1 -> 0.02
B22: Marge d'EBIT (%) | C22: =C7/C6 -> 0.021714286 | D22: =D7/D6 -> 0.022900763 | E22: =E7/E6 -> 0.0196515 | F22: =F7/F6 -> 0.02 | G22: =G7/G6 -> 0.02 | H22: =H7/H6 -> 0.02 | I22: =I7/I6 -> 0.02 | J22: =J7/J6 -> 0.02
B23: Marge d'EBITDA (%) | C23: =C9/C6 -> 0.055714286 | D23: =D9/D6 -> 0.056900763 | E23: =E9/E6 -> 0.064569216 | F23: =F9/F6 -> 0.064917715 | G23: =G9/G6 -> 0.064917715 | H23: =H9/H6 -> 0.064917715 | I23: =I9/I6 -> 0.064917715 | J23: =J9/J6 -> 0.064917715
B25: Rupture de périmètre : FY2023A est 100% organique ; FY2024A inclut ~2 mois d'Unieuro (acquis nov. 2024) ; FY2025A inclut Unieuro en année pleine. La croissance FY2024A -> FY2025A n'est donc pas comparable terme à terme (voir Cover).

Sheet Balance Sheet
B2: Bilan
B3: Toutes les valeurs sont en millions d'euros (M€). FY2025A (col. E) = ancre réelle + reconstruction (voir Assumptions).
C5: FY2023A | D5: FY2024A | E5: FY2025A | F5: FY2026F | G5: FY2027F | H5: FY2028F | I5: FY2029F | J5: FY2030F
B6: ACTIF
B7: Trésorerie | E7: =Assumptions!$C$6 -> 1104 | F7: =E7+'Cash Flow'!F18 -> 892.7903 | G7: =F7+'Cash Flow'!G18 -> 804.11994 | H7: =G7+'Cash Flow'!H18 -> 916.80456 | I7: =H7+'Cash Flow'!I18 -> 1199.3734 | J7: =I7+'Cash Flow'!J18 -> 1488.5812
B8: Créances clients | E8: ='Working Capital Schedule'!E15 -> 349 | F8: ='Working Capital Schedule'!F15 -> 355.98 | G8: ='Working Capital Schedule'!G15 -> 363.0996 | H8: ='Working Capital Schedule'!H15 -> 370.36159 | I8: ='Working Capital Schedule'!I15 -> 377.76882 | J8: ='Working Capital Schedule'!J15 -> 385.3242
B9: Stocks | E9: ='Working Capital Schedule'!E16 -> 1333 | F9: ='Working Capital Schedule'!F16 -> 1359.66 | G9: ='Working Capital Schedule'!G16 -> 1386.8532 | H9: ='Working Capital Schedule'!H16 -> 1414.5903 | I9: ='Working Capital Schedule'!I16 -> 1442.8821 | J9: ='Working Capital Schedule'!J16 -> 1471.7397
B10: Immobilisations (PP&E + droits d'usage IFRS16) | E10: ='PP&E Schedule'!E10 -> 3493 | F10: ='PP&E Schedule'!F10 -> 3283.135 | G10: ='PP&E Schedule'!G10 -> 3069.0727 | H10: ='PP&E Schedule'!H10 -> 2850.7292 | I10: ='PP&E Schedule'!I10 -> 2628.0187 | J10: ='PP&E Schedule'!J10 -> 2400.8541
B11: Goodwill et incorporels | E11: =Assumptions!$C$10 -> 2264 | F11: =E11 -> 2264 | G11: =F11 -> 2264 | H11: =G11 -> 2264 | I11: =H11 -> 2264 | J11: =I11 -> 2264
B12: TOTAL ACTIF | E12: =SUM(E7:E11) -> 8543 | F12: =SUM(F7:F11) -> 8155.5653 | G12: =SUM(G7:G11) -> 7887.1454 | H12: =SUM(H7:H11) -> 7816.4856 | I12: =SUM(I7:I11) -> 7912.0431 | J12: =SUM(J7:J11) -> 8010.4992
B14: PASSIF ET CAPITAUX PROPRES
B15: Dettes fournisseurs | E15: ='Working Capital Schedule'!E17 -> 1297 | F15: ='Working Capital Schedule'!F17 -> 1322.94 | G15: ='Working Capital Schedule'!G17 -> 1349.3988 | H15: ='Working Capital Schedule'!H17 -> 1376.3868 | I15: ='Working Capital Schedule'!I17 -> 1403.9145 | J15: ='Working Capital Schedule'!J17 -> 1431.9928
B16: Dettes locatives (IFRS16) | E16: =Assumptions!$C$12 -> 3135 | F16: =E16 -> 3135 | G16: =F16 -> 3135 | H16: =G16 -> 3135 | I16: =H16 -> 3135 | J16: =I16 -> 3135
B17: Dette financière brute | E17: ='Debt Schedule'!E14 -> 958 | F17: ='Debt Schedule'!F14 -> 506 | G17: ='Debt Schedule'!G14 -> 159.60485 | H17: ='Debt Schedule'!H14 -> 0 | I17: ='Debt Schedule'!I14 -> 0 | J17: ='Debt Schedule'!J14 -> 0
B18: Autres passifs | E18: =Assumptions!$C$14 -> 1577 | F18: =E18 -> 1577 | G18: =F18 -> 1577 | H18: =G18 -> 1577 | I18: =H18 -> 1577 | J18: =I18 -> 1577
B19: Capitaux propres | E19: =Assumptions!$C$15 -> 1576 | F19: =E19+'Income Statement'!F15-'Income Statement'!F18 -> 1614.6253 | G19: =F19+'Income Statement'!G15-'Income Statement'!G18 -> 1666.1418 | H19: =G19+'Income Statement'!H15-'Income Statement'!H18 -> 1728.0988 | I19: =H19+'Income Statement'!I15-'Income Statement'!I18 -> 1796.1286 | J19: =I19+'Income Statement'!J15-'Income Statement'!J18 -> 1866.5064
B20: TOTAL PASSIF ET CAPITAUX PROPRES | E20: =SUM(E15:E19) -> 8543 | F20: =SUM(F15:F19) -> 8155.5653 | G20: =SUM(G15:G19) -> 7887.1454 | H20: =SUM(H15:H19) -> 7816.4856 | I20: =SUM(I15:I19) -> 7912.0431 | J20: =SUM(J15:J19) -> 8010.4992
B22: Écart (contrôle d'équilibre, doit être nul) | E22: =E12-E20 -> 0 | F22: =F12-F20 -> 0 | G22: =G12-G20 -> 0 | H22: =H12-H20 -> 0 | I22: =I12-I20 -> 0 | J22: =J12-J20 -> 0

Sheet Cash Flow
B2: Tableau de flux de trésorerie
B3: Toutes les valeurs sont en millions d'euros (M€). FY2026F-FY2030F uniquement (pas d'historique reconstitué).
F5: FY2026F | G5: FY2027F | H5: FY2028F | I5: FY2029F | J5: FY2030F
B6: Résultat net | F6: ='Income Statement'!F15 -> 55.179 | G6: ='Income Statement'!G15 -> 73.59498 | H6: ='Income Statement'!H15 -> 88.510016 | I6: ='Income Statement'!I15 -> 97.185363 | J6: ='Income Statement'!J15 -> 100.53982
B7: + D&A | F7: ='Income Statement'!F8 -> 473.28 | G7: ='Income Statement'!G8 -> 482.7456 | H7: ='Income Statement'!H8 -> 492.40051 | I7: ='Income Statement'!I8 -> 502.24852 | J7: ='Income Statement'!J8 -> 512.29349
B8: +/- Variation de BFR | F8: ='Working Capital Schedule'!F24 -> -7.7 | G8: ='Working Capital Schedule'!G24 -> -7.854 | H8: ='Working Capital Schedule'!H24 -> -8.01108 | I8: ='Working Capital Schedule'!I24 -> -8.1713016 | J8: ='Working Capital Schedule'!J24 -> -8.3347276
B9: -> Flux de trésorerie d'exploitation | F9: =SUM(F6:F8) -> 520.759 | G9: =SUM(G6:G8) -> 548.48658 | H9: =SUM(H6:H8) -> 572.89945 | I9: =SUM(I6:I8) -> 591.26258 | J9: =SUM(J6:J8) -> 604.49859
B11: - Capex | F11: =-'PP&E Schedule'!F8 -> -263.415 | G11: =-'PP&E Schedule'!G8 -> -268.6833 | H11: =-'PP&E Schedule'!H8 -> -274.05697 | I11: =-'PP&E Schedule'!I8 -> -279.53811 | J11: =-'PP&E Schedule'!J8 -> -285.12887
B12: -> Flux de trésorerie d'investissement (= -Capex) | F12: =F11 -> -263.415 | G12: =G11 -> -268.6833 | H12: =H11 -> -274.05697 | I12: =I11 -> -279.53811 | J12: =J11 -> -285.12887
B14: +/- Remboursement de dette (programmé + sweep) | F14: ='Debt Schedule'!F15 -> -452 | G14: ='Debt Schedule'!G15 -> -346.39515 | H14: ='Debt Schedule'!H15 -> -159.60485 | I14: ='Debt Schedule'!I15 -> 0 | J14: ='Debt Schedule'!J15 -> 0
B15: - Dividendes versés | F15: =-'Income Statement'!F18 -> -16.5537 | G15: =-'Income Statement'!G18 -> -22.078494 | H15: =-'Income Statement'!H18 -> -26.553005 | I15: =-'Income Statement'!I18 -> -29.155609 | J15: =-'Income Statement'!J18 -> -30.161946
B16: -> Flux de trésorerie de financement | F16: =SUM(F14:F15) -> -468.5537 | G16: =SUM(G14:G15) -> -368.47364 | H16: =SUM(H14:H15) -> -186.15785 | I16: =SUM(I14:I15) -> -29.155609 | J16: =SUM(J14:J15) -> -30.161946
B18: -> Variation de trésorerie | F18: =F9+F12+F16 -> -211.2097 | G18: =G9+G12+G16 -> -88.670364 | H18: =H9+H12+H16 -> 112.68463 | I18: =I9+I12+I16 -> 282.56887 | J18: =J9+J12+J16 -> 289.20777

Sheet DCF
B2: Valorisation DCF
B3: Toutes les valeurs sont en millions d'euros (M€), sauf mention contraire. FCFF non levier, actualisé au WACC.
F5: FY2026F | G5: FY2027F | H5: FY2028F | I5: FY2029F | J5: FY2030F
B6: FLUX DE TRÉSORERIE DISPONIBLES NON LEVIER (FCFF)
B7: EBIT | F7: ='Income Statement'!F7 -> 210.732 | G7: ='Income Statement'!G7 -> 214.94664 | H7: ='Income Statement'!H7 -> 219.24557 | I7: ='Income Statement'!I7 -> 223.63048 | J7: ='Income Statement'!J7 -> 228.10309
B8: x (1 - taux d'IS) | F8: =1-Assumptions!$C$29 -> 0.75 | G8: =1-Assumptions!$C$29 -> 0.75 | H8: =1-Assumptions!$C$29 -> 0.75 | I8: =1-Assumptions!$C$29 -> 0.75 | J8: =1-Assumptions!$C$29 -> 0.75
B9: NOPAT (EBIT après impôt) | F9: =F7*F8 -> 158.049 | G9: =G7*G8 -> 161.20998 | H9: =H7*H8 -> 164.43418 | I9: =I7*I8 -> 167.72286 | J9: =J7*J8 -> 171.07732
B10: + D&A | F10: ='Income Statement'!F8 -> 473.28 | G10: ='Income Statement'!G8 -> 482.7456 | H10: ='Income Statement'!H8 -> 492.40051 | I10: ='Income Statement'!I8 -> 502.24852 | J10: ='Income Statement'!J8 -> 512.29349
B11: - Capex | F11: =-'PP&E Schedule'!F8 -> -263.415 | G11: =-'PP&E Schedule'!G8 -> -268.6833 | H11: =-'PP&E Schedule'!H8 -> -274.05697 | I11: =-'PP&E Schedule'!I8 -> -279.53811 | J11: =-'PP&E Schedule'!J8 -> -285.12887
B12: +/- Variation de BFR | F12: ='Working Capital Schedule'!F24 -> -7.7 | G12: ='Working Capital Schedule'!G24 -> -7.854 | H12: ='Working Capital Schedule'!H24 -> -8.01108 | I12: ='Working Capital Schedule'!I24 -> -8.1713016 | J12: ='Working Capital Schedule'!J24 -> -8.3347276
B13: -> FCFF (flux de trésorerie disponibles non levier) | F13: =SUM(F9:F12) -> 360.214 | G13: =SUM(G9:G12) -> 367.41828 | H13: =SUM(H9:H12) -> 374.76665 | I13: =SUM(I9:I12) -> 382.26198 | J13: =SUM(J9:J12) -> 389.90722
B15: ACTUALISATION
B16: WACC (réf. Assumptions) | F16: =Assumptions!$C$57 -> 0.070002765 | G16: =Assumptions!$C$57 -> 0.070002765 | H16: =Assumptions!$C$57 -> 0.070002765 | I16: =Assumptions!$C$57 -> 0.070002765 | J16: =Assumptions!$C$57 -> 0.070002765
B17: Période d'actualisation (années) | F17: 1 | G17: 2 | H17: 3 | I17: 4 | J17: 5
B18: Facteur d'actualisation | F18: =1/(1+F16)^F17 -> 0.93457702 | G18: =1/(1+G16)^G17 -> 0.87343421 | H18: =1/(1+H16)^H17 -> 0.81629155 | I18: =1/(1+I16)^I17 -> 0.76288733 | J18: =1/(1+J16)^J17 -> 0.71297697
B19: FCFF actualisé (valeur actuelle) | F19: =F13*F18 -> 336.64773 | G19: =G13*G18 -> 320.9157 | H19: =H13*H18 -> 305.91885 | I19: =I13*I18 -> 291.62282 | J19: =J13*J18 -> 277.99487
B21: VALEUR TERMINALE (Gordon-Shapiro, FCFF normalisé)
B22: FCFF terminal normalisé (capex = D&A en régime stationnaire, voir note) | C22: =J9-('Working Capital Schedule'!$J$18*Assumptions!$C$58) -> 164.70125
B23: Croissance terminale (réf. Assumptions) | C23: =Assumptions!$C$58 -> 0.015
B24: Valeur terminale (fin FY2030F) | C24: =C22*(1+C23)/(J16-C23) -> 3039.334
B25: Facteur d'actualisation (année 5) | C25: =J18 -> 0.71297697
B26: Valeur terminale actualisée (valeur actuelle) | C26: =C24*C25 -> 2166.9751
B28: VALEUR D'ENTREPRISE ET PONT VERS LA VALEUR PAR ACTION
B29: Somme des FCFF actualisés (5 ans) | C29: =SUM(F19:J19) -> 1533.1
B30: + Valeur terminale actualisée | C30: =C26 -> 2166.9751
B31: -> Valeur d'entreprise (VE) | C31: =C29+C30 -> 3700.0751
B32: - Dette nette y compris IFRS16 (réf. Assumptions) | C32: =Assumptions!$C$61 -> 2989
B33: -> Valeur des capitaux propres (equity value) | C33: =C31-C32 -> 711.07507
B34: Actions en circulation (millions, réf. Assumptions) | C34: =Assumptions!$C$39 -> 29.37
B35: -> Valeur par action implicite (DCF) | C35: =C33/C34 -> 24.210932
B36: Cours de marché réel (réf. Assumptions) | C36: =Assumptions!$C$38 -> 34.4
B37: Écart valeur implicite vs cours de marché (%) | C37: =C35/C36-1 -> -0.29619384
B39: LECTURE CROISÉE (multiples implicites)
B40: EBITDA FY2025A réel (réf. Assumptions) | C40: =Assumptions!$C$44 -> 667
B41: VE implicite du DCF / EBITDA FY2025A réel | C41: =C31/C40 -> 5.5473389
B42: VE réelle actuelle / EBITDA FY2025A réel, y compris IFRS16 | C42: =Assumptions!$C$63 -> 5.995994
B44: Lecture : le multiple implicite du DCF et le multiple réel (y compris IFRS16) sont proches ; voir Checks.
B46: Note méthodologique IFRS16 : sur les 5 années explicites, le D&A modélisé (4,5 % du CA, cohérent avec le réel FY2025A qui inclut l'amortissement des droits d'usage IFRS16) dépasse le capex (2,5 % du CA, proche du capex réel publié) - un écart réel pour un réseau mature, pas une erreur. Pour éviter de prolonger cet écart à l'infini dans la valeur terminale, le FCFF terminal (ligne 22) est normalisé : capex terminal = D&A terminal (régime stationnaire), convention standard pour une perpétuité - voir PP&E Schedule.

Sheet Sensitivity
B2: Sensibilité : valeur par action implicite
B3: Grille WACC x croissance terminale. Formules SUMPRODUCT (pas de Data Table Excel), pour rester robuste à l'export/au recalcul.
B5: GRILLE DE SENSIBILITÉ - VALEUR PAR ACTION IMPLICITE (€)
B6: WACC \ croissance terminale | D6: =Assumptions!$C$58+(-0.01) -> 0.005 | E6: =Assumptions!$C$58+(-0.005) -> 0.01 | F6: =Assumptions!$C$58+(0) -> 0.015 | G6: =Assumptions!$C$58+(0.005) -> 0.02 | H6: =Assumptions!$C$58+(0.01) -> 0.025
B7: =Assumptions!$C$57+(-0.01) -> 0.060002765 | D7: =(SUMPRODUCT(DCF!$F$13:$J$13,1/(1+$B7)^DCF!$F$17:$J$17)+(DCF!$J$9-'Working Capital Schedule'!$J$18*D$6)*(1+D$6)/($B7-D$6)/(1+$B7)^5-Assumptions!$C$61)/Assumptions!$C$39 -> 30.419565 | E7: =(SUMPRODUCT(DCF!$F$13:$J$13,1/(1+$B7)^DCF!$F$17:$J$17)+(DCF!$J$9-'Working Capital Schedule'!$J$18*E$6)*(1+E$6)/($B7-E$6)/(1+$B7)^5-Assumptions!$C$61)/Assumptions!$C$39 -> 37.61099 | F7: =(SUMPRODUCT(DCF!$F$13:$J$13,1/(1+$B7)^DCF!$F$17:$J$17)+(DCF!$J$9-'Working Capital Schedule'!$J$18*F$6)*(1+F$6)/($B7-F$6)/(1+$B7)^5-Assumptions!$C$61)/Assumptions!$C$39 -> 46.388395 | G7: =(SUMPRODUCT(DCF!$F$13:$J$13,1/(1+$B7)^DCF!$F$17:$J$17)+(DCF!$J$9-'Working Capital Schedule'!$J$18*G$6)*(1+G$6)/($B7-G$6)/(1+$B7)^5-Assumptions!$C$61)/Assumptions!$C$39 -> 57.346482 | H7: =(SUMPRODUCT(DCF!$F$13:$J$13,1/(1+$B7)^DCF!$F$17:$J$17)+(DCF!$J$9-'Working Capital Schedule'!$J$18*H$6)*(1+H$6)/($B7-H$6)/(1+$B7)^5-Assumptions!$C$61)/Assumptions!$C$39 -> 71.419755
B8: =Assumptions!$C$57+(-0.005) -> 0.065002765 | D8: =(SUMPRODUCT(DCF!$F$13:$J$13,1/(1+$B8)^DCF!$F$17:$J$17)+(DCF!$J$9-'Working Capital Schedule'!$J$18*D$6)*(1+D$6)/($B8-D$6)/(1+$B8)^5-Assumptions!$C$61)/Assumptions!$C$39 -> 21.468611 | E8: =(SUMPRODUCT(DCF!$F$13:$J$13,1/(1+$B8)^DCF!$F$17:$J$17)+(DCF!$J$9-'Working Capital Schedule'!$J$18*E$6)*(1+E$6)/($B8-E$6)/(1+$B8)^5-Assumptions!$C$61)/Assumptions!$C$39 -> 27.273143 | F8: =(SUMPRODUCT(DCF!$F$13:$J$13,1/(1+$B8)^DCF!$F$17:$J$17)+(DCF!$J$9-'Working Capital Schedule'!$J$18*F$6)*(1+F$6)/($B8-F$6)/(1+$B8)^5-Assumptions!$C$61)/Assumptions!$C$39 -> 34.227954 | G8: =(SUMPRODUCT(DCF!$F$13:$J$13,1/(1+$B8)^DCF!$F$17:$J$17)+(DCF!$J$9-'Working Capital Schedule'!$J$18*G$6)*(1+G$6)/($B8-G$6)/(1+$B8)^5-Assumptions!$C$61)/Assumptions!$C$39 -> 42.716448 | H8: =(SUMPRODUCT(DCF!$F$13:$J$13,1/(1+$B8)^DCF!$F$17:$J$17)+(DCF!$J$9-'Working Capital Schedule'!$J$18*H$6)*(1+H$6)/($B8-H$6)/(1+$B8)^5-Assumptions!$C$61)/Assumptions!$C$39 -> 53.313715
B9: =Assumptions!$C$57+(0) -> 0.070002765 | D9: =(SUMPRODUCT(DCF!$F$13:$J$13,1/(1+$B9)^DCF!$F$17:$J$17)+(DCF!$J$9-'Working Capital Schedule'!$J$18*D$6)*(1+D$6)/($B9-D$6)/(1+$B9)^5-Assumptions!$C$61)/Assumptions!$C$39 -> 13.840654 | E9: =(SUMPRODUCT(DCF!$F$13:$J$13,1/(1+$B9)^DCF!$F$17:$J$17)+(DCF!$J$9-'Working Capital Schedule'!$J$18*E$6)*(1+E$6)/($B9-E$6)/(1+$B9)^5-Assumptions!$C$61)/Assumptions!$C$39 -> 18.598017 | F9: =(SUMPRODUCT(DCF!$F$13:$J$13,1/(1+$B9)^DCF!$F$17:$J$17)+(DCF!$J$9-'Working Capital Schedule'!$J$18*F$6)*(1+F$6)/($B9-F$6)/(1+$B9)^5-Assumptions!$C$61)/Assumptions!$C$39 -> 24.210932 | G9: =(SUMPRODUCT(DCF!$F$13:$J$13,1/(1+$B9)^DCF!$F$17:$J$17)+(DCF!$J$9-'Working Capital Schedule'!$J$18*G$6)*(1+G$6)/($B9-G$6)/(1+$B9)^5-Assumptions!$C$61)/Assumptions!$C$39 -> 30.936049 | H9: =(SUMPRODUCT(DCF!$F$13:$J$13,1/(1+$B9)^DCF!$F$17:$J$17)+(DCF!$J$9-'Working Capital Schedule'!$J$18*H$6)*(1+H$6)/($B9-H$6)/(1+$B9)^5-Assumptions!$C$61)/Assumptions!$C$39 -> 39.14408
B10: =Assumptions!$C$57+(0.005) -> 0.075002765 | D10: =(SUMPRODUCT(DCF!$F$13:$J$13,1/(1+$B10)^DCF!$F$17:$J$17)+(DCF!$J$9-'Working Capital Schedule'!$J$18*D$6)*(1+D$6)/($B10-D$6)/(1+$B10)^5-Assumptions!$C$61)/Assumptions!$C$39 -> 7.2538404 | E10: =(SUMPRODUCT(DCF!$F$13:$J$13,1/(1+$B10)^DCF!$F$17:$J$17)+(DCF!$J$9-'Working Capital Schedule'!$J$18*E$6)*(1+E$6)/($B10-E$6)/(1+$B10)^5-Assumptions!$C$61)/Assumptions!$C$39 -> 11.203728 | F10: =(SUMPRODUCT(DCF!$F$13:$J$13,1/(1+$B10)^DCF!$F$17:$J$17)+(DCF!$J$9-'Working Capital Schedule'!$J$18*F$6)*(1+F$6)/($B10-F$6)/(1+$B10)^5-Assumptions!$C$61)/Assumptions!$C$39 -> 15.803499 | G10: =(SUMPRODUCT(DCF!$F$13:$J$13,1/(1+$B10)^DCF!$F$17:$J$17)+(DCF!$J$9-'Working Capital Schedule'!$J$18*G$6)*(1+G$6)/($B10-G$6)/(1+$B10)^5-Assumptions!$C$61)/Assumptions!$C$39 -> 21.230385 | H10: =(SUMPRODUCT(DCF!$F$13:$J$13,1/(1+$B10)^DCF!$F$17:$J$17)+(DCF!$J$9-'Working Capital Schedule'!$J$18*H$6)*(1+H$6)/($B10-H$6)/(1+$B10)^5-Assumptions!$C$61)/Assumptions!$C$39 -> 27.732509
B11: =Assumptions!$C$57+(0.01) -> 0.080002765 | D11: =(SUMPRODUCT(DCF!$F$13:$J$13,1/(1+$B11)^DCF!$F$17:$J$17)+(DCF!$J$9-'Working Capital Schedule'!$J$18*D$6)*(1+D$6)/($B11-D$6)/(1+$B11)^5-Assumptions!$C$61)/Assumptions!$C$39 -> 1.5014174 | E11: =(SUMPRODUCT(DCF!$F$13:$J$13,1/(1+$B11)^DCF!$F$17:$J$17)+(DCF!$J$9-'Working Capital Schedule'!$J$18*E$6)*(1+E$6)/($B11-E$6)/(1+$B11)^5-Assumptions!$C$61)/Assumptions!$C$39 -> 4.8174327 | F11: =(SUMPRODUCT(DCF!$F$13:$J$13,1/(1+$B11)^DCF!$F$17:$J$17)+(DCF!$J$9-'Working Capital Schedule'!$J$18*F$6)*(1+F$6)/($B11-F$6)/(1+$B11)^5-Assumptions!$C$61)/Assumptions!$C$39 -> 8.6360059 | G11: =(SUMPRODUCT(DCF!$F$13:$J$13,1/(1+$B11)^DCF!$F$17:$J$17)+(DCF!$J$9-'Working Capital Schedule'!$J$18*G$6)*(1+G$6)/($B11-G$6)/(1+$B11)^5-Assumptions!$C$61)/Assumptions!$C$39 -> 13.082771 | H11: =(SUMPRODUCT(DCF!$F$13:$J$13,1/(1+$B11)^DCF!$F$17:$J$17)+(DCF!$J$9-'Working Capital Schedule'!$J$18*H$6)*(1+H$6)/($B11-H$6)/(1+$B11)^5-Assumptions!$C$61)/Assumptions!$C$39 -> 18.329044
B13: Lecture : chaque cellule recalcule la valeur d'entreprise (somme des FCFF actualisés au WACC de la ligne + valeur terminale actualisée à la croissance de la colonne), déduit la dette nette y compris IFRS16 et divise par le nombre d'actions - exactement la même mécanique que l'onglet DCF, rejouée pour chaque couple (WACC, g).
B15: RAPPEL : SCÉNARIO CENTRAL (onglet DCF)
B16: WACC central | C16: =Assumptions!$C$57 -> 0.070002765
B17: Croissance terminale centrale | C17: =Assumptions!$C$58 -> 0.015
B18: Valeur par action implicite (scénario central) | C18: =DCF!C35 -> 24.210932
B19: Cours de marché réel | C19: =DCF!C36 -> 34.4

Sheet Dashboard
B2: Dashboard : graphiques de synthèse
B3: Toutes les valeurs sont en millions d'euros (M€), sauf mention contraire.
C5: FY2023A | D5: FY2024A | E5: FY2025A | F5: FY2026F | G5: FY2027F | H5: FY2028F | I5: FY2029F | J5: FY2030F
B6: COMPTE DE RÉSULTAT
B7: Chiffre d'affaires | C7: ='Income Statement'!C6 -> 7875 | D7: ='Income Statement'!D6 -> 8253 | E7: ='Income Statement'!E6 -> 10330 | F7: ='Income Statement'!F6 -> 10536.6 | G7: ='Income Statement'!G6 -> 10747.332 | H7: ='Income Statement'!H6 -> 10962.279 | I7: ='Income Statement'!I6 -> 11181.524 | J7: ='Income Statement'!J6 -> 11405.155
B8: Marge d'EBIT (%) | C8: ='Income Statement'!C22 -> 0.021714286 | D8: ='Income Statement'!D22 -> 0.022900763 | E8: ='Income Statement'!E22 -> 0.0196515 | F8: ='Income Statement'!F22 -> 0.02 | G8: ='Income Statement'!G22 -> 0.02 | H8: ='Income Statement'!H22 -> 0.02 | I8: ='Income Statement'!I22 -> 0.02 | J8: ='Income Statement'!J22 -> 0.02
B9: Marge nette (résultat net / CA, %) | C9: ='Income Statement'!C15/'Income Statement'!C6 -> 0.0063492063 | D9: ='Income Statement'!D15/'Income Statement'!D6 -> 0.0043620502 | E9: ='Income Statement'!E15/'Income Statement'!E6 -> -0.014133591 | F9: ='Income Statement'!F15/'Income Statement'!F6 -> 0.0052368886 | G9: ='Income Statement'!G15/'Income Statement'!G6 -> 0.0068477442 | H9: ='Income Statement'!H15/'Income Statement'!H6 -> 0.0080740527 | I9: ='Income Statement'!I15/'Income Statement'!I6 -> 0.0086916024 | J9: ='Income Statement'!J15/'Income Statement'!J6 -> 0.0088152965
B11: TABLEAU DE FLUX DE TRÉSORERIE (FY2026F-FY2030F)
C12: FY2026F | D12: FY2027F | E12: FY2028F | F12: FY2029F | G12: FY2030F
B13: Exploitation | C13: ='Cash Flow'!F9 -> 520.759 | D13: ='Cash Flow'!G9 -> 548.48658 | E13: ='Cash Flow'!H9 -> 572.89945 | F13: ='Cash Flow'!I9 -> 591.26258 | G13: ='Cash Flow'!J9 -> 604.49859
B14: Investissement | C14: ='Cash Flow'!F12 -> -263.415 | D14: ='Cash Flow'!G12 -> -268.6833 | E14: ='Cash Flow'!H12 -> -274.05697 | F14: ='Cash Flow'!I12 -> -279.53811 | G14: ='Cash Flow'!J12 -> -285.12887
B15: Financement | C15: ='Cash Flow'!F16 -> -468.5537 | D15: ='Cash Flow'!G16 -> -368.47364 | E15: ='Cash Flow'!H16 -> -186.15785 | F15: ='Cash Flow'!I16 -> -29.155609 | G15: ='Cash Flow'!J16 -> -30.161946
B16: Variation de trésorerie | C16: =C13+C14+C15 -> -211.2097 | D16: =D13+D14+D15 -> -88.670364 | E16: =E13+E14+E15 -> 112.68463 | F16: =F13+F14+F15 -> 282.56887 | G16: =G13+G14+G15 -> 289.20777
B18: VALORISATION (DCF, scénario central)
B19: Valeur par action implicite (DCF) | C19: =DCF!C35 -> 24.210932
B20: Cours de marché réel | C20: =DCF!C36 -> 34.4

Sheet Checks
B2: Contrôles de cohérence
B5: Contrôle | D5: Résultat
B6: Bilan équilibré chaque année FY2025A-FY2030F (actif = passif + capitaux propres) | D6: =IF(SUMPRODUCT(--(ROUND('Balance Sheet'!E22:J22,1)=0))=6,"OK","A VERIFIER") -> OK
B7: Bilan d'ouverture FY2025A équilibré (Assumptions) | D7: =IF(ROUND(Assumptions!C19,1)=0,"OK","A VERIFIER") -> OK
B8: Trésorerie jamais négative sur l'horizon | D8: =IF(MIN('Balance Sheet'!E7:J7)>=0,"OK","A VERIFIER") -> OK
B9: Dette financière brute jamais négative sur l'horizon | D9: =IF(MIN('Balance Sheet'!E17:J17)>=0,"OK","A VERIFIER") -> OK
B10: Capitaux propres positifs sur l'horizon | D10: =IF(MIN('Balance Sheet'!E19:J19)>0,"OK","A VERIFIER") -> OK
B11: Immobilisations (PP&E Schedule) jamais négatives sur l'horizon | D11: =IF(MIN('PP&E Schedule'!F10:J10)>=0,"OK","A VERIFIER") -> OK
B12: Dette financière (Debt Schedule) jamais négative sur l'horizon | D12: =IF(MIN('Debt Schedule'!F14:J14)>=0,"OK","A VERIFIER") -> OK
B13: Le sweep de trésorerie ne dépasse jamais la dette restante | D13: =IF(SUMPRODUCT(--(('Debt Schedule'!F13:J13)>=-('Debt Schedule'!F8:J8+'Debt Schedule'!F9:J9)-0.01))=5,"OK","A VERIFIER") -> OK
B14: WACC > croissance terminale (condition de validité du Gordon-Shapiro) | D14: =IF(Assumptions!C57>Assumptions!C58,"OK","A VERIFIER") -> OK
B15: Valeur d'entreprise (DCF) positive | D15: =IF(DCF!C31>0,"OK","A VERIFIER") -> OK
B16: Grille de sensibilité : cellule centrale cohérente avec la valeur DCF | D16: =IF(ROUND(Sensitivity!F9,2)=ROUND(DCF!C35,2),"OK","A VERIFIER") -> OK
B17: Working Capital Schedule : BFR du bilan = BFR de la schedule | D17: =IF(SUMPRODUCT(--(ROUND('Balance Sheet'!F8:J8-'Working Capital Schedule'!F15:J15,1)=0))=5,"OK","A VERIFIER") -> OK
B19: Synthèse | C19: =IF(COUNTIF(D6:D17,"OK")=12,"Tous les contrôles sont OK","Au moins un contrôle à vérifier") -> Tous les contrôles sont OK
